Workbook

Sheet data asli x100
A2: PENGAMATAN PASANG SURUT WOLO-KOLAKA
A3: SELAMA 30 HARI
L5: Data Pengamatan Pasang Surut 30 Hari
A6: No. | B6: Tanggal dan Jam Pengamtan | C6: Elevasi Pasut | L6: No. | M6: Tanggal | N6: Jam
C7: cm | D7: m | N7: 0 | O7: 0.041666667 | P7: 0.083333333 | Q7: 0.125 | R7: 0.16666667 | S7: 0.20833333 | T7: 0.25 | U7: 0.29166667 | V7: 0.33333333 | W7: 0.375 | X7: 0.41666667 | Y7: 0.45833333 | Z7: 0.5 | AA7: 0.54166667 | AB7: 0.58333333 | AC7: 0.625 | AD7: 0.66666667 | AE7: 0.70833333 | AF7: 0.75 | AG7: 0.79166667 | AH7: 0.83333333 | AI7: 0.875 | AJ7: 0.91666667 | AK7: 0.95833333
A8: =A7+1 -> 1 | B8: 44709 | C8: =D8*100 -> 136 | D8: 1.36 | F8: =D8-0.5 -> 0.86 | L8: 1 | M8: 43599 | N8: {=TRANSPOSE(D8:D31)} -> 1.36 | O8: 1.655 | P8: 1.983 | Q8: 2.247 | R8: 2.39 | S8: 2.43 | T8: 2.317 | U8: 2.121 | V8: 1.884 | W8: 1.637 | X8: 1.454 | Y8: 1.354 | Z8: 1.42 | AA8: 1.561 | AB8: 1.731 | AC8: 1.889 | AD8: 1.949 | AE8: 1.9 | AF8: 1.733 | AG8: 1.55 | AH8: 1.324 | AI8: 1.108 | AJ8: 0.969 | AK8: 0.991
A9: =A8+1 -> 2 | B9: 44709.042 | C9: =D9*100 -> 165.5 | D9: 1.655 | F9: =D9-0.5 -> 1.155 | L9: 2 | M9: 43600 | N9: {=TRANSPOSE(D32:D55)} -> 1.138 | O9: 1.439 | P9: 1.847 | Q9: 2.223 | R9: 2.491 | S9: 2.581 | T9: 2.519 | U9: 2.326 | V9: 2.024 | W9: 1.719 | X9: 1.441 | Y9: 1.253 | Z9: 1.232 | AA9: 1.332 | AB9: 1.5 | AC9: 1.693 | AD9: 1.833 | AE9: 1.84 | AF9: 1.742 | AG9: 1.583 | AH9: 1.332 | AI9: 1.067 | AJ9: 0.813 | AK9: 0.754
A10: =A9+1 -> 3 | B10: 44709.083 | C10: =D10*100 -> 198.3 | D10: 1.983 | F10: =D10-0.5 -> 1.483 | L10: 3 | M10: 43601 | N10: {=TRANSPOSE(D56:D79)} -> 0.906 | O10: 1.231 | P10: 1.627 | Q10: 2.055 | R10: 2.456 | S10: 2.714 | T10: 2.728 | U10: 2.552 | V10: 2.228 | W10: 1.828 | X10: 1.485 | Y10: 1.22 | Z10: 1.136 | AA10: 1.234 | AB10: 1.434 | AC10: 1.641 | AD10: 1.778 | AE10: 1.821 | AF10: 1.787 | AG10: 1.626 | AH10: 1.399 | AI10: 1.146 | AJ10: 0.885 | AK10: 0.702
A11: =A10+1 -> 4 | B11: 44709.125 | C11: =D11*100 -> 224.7 | D11: 2.247 | F11: =D11-0.5 -> 1.747 | L11: 4 | M11: 43602 | N11: {=TRANSPOSE(D80:D103)} -> 0.743 | O11: 1.009 | P11: 1.395 | Q11: 1.884 | R11: 2.352 | S11: 2.696 | T11: 2.815 | U11: 2.738 | V11: 2.46 | W11: 2.028 | X11: 1.653 | Y11: 1.345 | Z11: 1.18 | AA11: 1.152 | AB11: 1.261 | AC11: 1.47 | AD11: 1.668 | AE11: 1.771 | AF11: 1.765 | AG11: 1.653 | AH11: 1.444 | AI11: 1.226 | AJ11: 0.956 | AK11: 0.738
A12: =A11+1 -> 5 | B12: 44709.167 | C12: =D12*100 -> 239 | D12: 2.39 | F12: =D12-0.5 -> 1.89 | L12: 5 | M12: 43603 | N12: {=TRANSPOSE(D104:D127)} -> 0.687 | O12: 0.864 | P12: 1.246 | Q12: 1.701 | R12: 2.193 | S12: 2.595 | T12: 2.818 | U12: 2.84 | V12: 2.657 | W12: 2.288 | X12: 1.882 | Y12: 1.515 | Z12: 1.27 | AA12: 1.169 | AB12: 1.225 | AC12: 1.375 | AD12: 1.594 | AE12: 1.784 | AF12: 1.839 | AG12: 1.745 | AH12: 1.554 | AI12: 1.295 | AJ12: 0.963 | AK12: 0.762
A13: =A12+1 -> 6 | B13: 44709.208 | C13: =D13*100 -> 243 | D13: 2.43 | F13: =D13-0.5 -> 1.93 | L13: 6 | M13: 43604 | N13: {=TRANSPOSE(D128:D151)} -> 0.658 | O13: 0.75 | P13: 1.061 | Q13: 1.493 | R13: 1.999 | S13: 2.435 | T13: 2.745 | U13: 2.846 | V13: 2.758 | W13: 2.506 | X13: 2.123 | Y13: 1.749 | Z13: 1.429 | AA13: 1.261 | AB13: 1.231 | AC13: 1.372 | AD13: 1.588 | AE13: 1.769 | AF13: 1.813 | AG13: 1.777 | AH13: 1.641 | AI13: 1.408 | AJ13: 1.151 | AK13: 0.904
A14: =A13+1 -> 7 | B14: 44709.25 | C14: =D14*100 -> 231.7 | D14: 2.317 | F14: =D14-0.5 -> 1.817 | L14: 7 | M14: 43605 | N14: {=TRANSPOSE(D152:D175)} -> 0.74 | O14: 0.754 | P14: 0.947 | Q14: 1.305 | R14: 1.754 | S14: 2.185 | T14: 2.547 | U14: 2.758 | V14: 2.773 | W14: 2.598 | X14: 2.278 | Y14: 1.887 | Z14: 1.562 | AA14: 1.349 | AB14: 1.28 | AC14: 1.35 | AD14: 1.527 | AE14: 1.68 | AF14: 1.779 | AG14: 1.766 | AH14: 1.683 | AI14: 1.475 | AJ14: 1.263 | AK14: 1.023
A15: =A14+1 -> 8 | B15: 44709.292 | C15: =D15*100 -> 212.1 | D15: 2.121 | F15: =D15-0.5 -> 1.621 | L15: 8 | M15: 43606 | N15: {=TRANSPOSE(D176:D199)} -> 0.797 | O15: 0.734 | P15: 0.857 | Q15: 1.16 | R15: 1.54 | S15: 1.989 | T15: 2.356 | U15: 2.595 | V15: 2.689 | W15: 2.586 | X15: 2.339 | Y15: 1.991 | Z15: 1.698 | AA15: 1.4355 | AB15: 1.319 | AC15: 1.304 | AD15: 1.421 | AE15: 1.594 | AF15: 1.748 | AG15: 1.82 | AH15: 1.771 | AI15: 1.588 | AJ15: 1.36 | AK15: 1.124
A16: =A15+1 -> 9 | B16: 44709.333 | C16: =D16*100 -> 188.4 | D16: 1.884 | F16: =D16-0.5 -> 1.384 | L16: 9 | M16: 43607 | N16: {=TRANSPOSE(D200:D223)} -> 0.905 | O16: 0.786 | P16: 0.845 | Q16: 1.07 | R16: 1.413 | S16: 1.792 | T16: 2.179 | U16: 2.442 | V16: 2.563 | W16: 2.552 | X16: 2.406 | Y16: 2.115 | Z16: 1.805 | AA16: 1.564 | AB16: 1.439 | AC16: 1.408 | AD16: 1.479 | AE16: 1.593 | AF16: 1.721 | AG16: 1.808 | AH16: 1.805 | AI16: 1.667 | AJ16: 1.46 | AK16: 1.254
A17: =A16+1 -> 10 | B17: 44709.375 | C17: =D17*100 -> 163.7 | D17: 1.637 | F17: =D17-0.5 -> 1.137 | L17: 10 | M17: 43608 | N17: {=TRANSPOSE(D224:D247)} -> 1.047 | O17: 0.906 | P17: 0.871 | Q17: 1.024 | R17: 1.314 | S17: 1.668 | T17: 1.993 | U17: 2.25 | V17: 2.402 | W17: 2.422 | X17: 2.357 | Y17: 2.183 | Z17: 1.923 | AA17: 1.705 | AB17: 1.556 | AC17: 1.473 | AD17: 1.479 | AE17: 1.573 | AF17: 1.673 | AG17: 1.789 | AH17: 1.832 | AI17: 1.755 | AJ17: 1.556 | AK17: 1.375
A18: =A17+1 -> 11 | B18: 44709.417 | C18: =D18*100 -> 145.4 | D18: 1.454 | F18: =D18-0.5 -> 0.954 | L18: 11 | M18: 43609 | N18: {=TRANSPOSE(D248:D271)} -> 1.197 | O18: 1.058 | P18: 1.028 | Q18: 1.1 | R18: 1.307 | S18: 1.593 | T18: 1.886 | U18: 2.096 | V18: 2.241 | W18: 2.303 | X18: 2.247 | Y18: 2.124 | Z18: 1.986 | AA18: 1.808 | AB18: 1.629 | AC18: 1.535 | AD18: 1.502 | AE18: 1.511 | AF18: 1.595 | AG18: 1.724 | AH18: 1.796 | AI18: 1.766 | AJ18: 1.64 | AK18: 1.495
A19: =A18+1 -> 12 | B19: 44709.458 | C19: =D19*100 -> 135.4 | D19: 1.354 | F19: =D19-0.5 -> 0.854 | L19: 12 | M19: 43610 | N19: {=TRANSPOSE(D272:D295)} -> 1.373 | O19: 1.271 | P19: 1.234 | Q19: 1.273 | R19: 1.352 | S19: 1.526 | T19: 1.739 | U19: 1.905 | V19: 2.039 | W19: 2.087 | X19: 2.077 | Y19: 2.036 | Z19: 1.976 | AA19: 1.873 | AB19: 1.765 | AC19: 1.632 | AD19: 1.578 | AE19: 1.538 | AF19: 1.544 | AG19: 1.621 | AH19: 1.704 | AI19: 1.721 | AJ19: 1.693 | AK19: 1.61
A20: =A19+1 -> 13 | B20: 44709.5 | C20: =D20*100 -> 142 | D20: 1.42 | F20: =D20-0.5 -> 0.92 | L20: 13 | M20: 43611 | N20: {=TRANSPOSE(D296:D319)} -> 1.496 | O20: 1.437 | P20: 1.431 | Q20: 1.466 | R20: 1.539 | S20: 1.636 | T20: 1.707 | U20: 1.797 | V20: 1.843 | W20: 1.874 | X20: 1.899 | Y20: 1.924 | Z20: 1.894 | AA20: 1.835 | AB20: 1.789 | AC20: 1.674 | AD20: 1.576 | AE20: 1.509 | AF20: 1.468 | AG20: 1.484 | AH20: 1.527 | AI20: 1.544 | AJ20: 1.584 | AK20: 1.569
A21: =A20+1 -> 14 | B21: 44709.542 | C21: =D21*100 -> 156.1 | D21: 1.561 | F21: =D21-0.5 -> 1.061 | L21: 14 | M21: 43612 | N21: {=TRANSPOSE(D320:D343)} -> 1.62 | O21: 1.676 | P21: 1.669 | Q21: 1.699 | R21: 1.714 | S21: 1.714 | T21: 1.712 | U21: 1.73 | V21: 1.752 | W21: 1.723 | X21: 1.715 | Y21: 1.739 | Z21: 1.785 | AA21: 1.822 | AB21: 1.823 | AC21: 1.766 | AD21: 1.684 | AE21: 1.548 | AF21: 1.422 | AG21: 1.365 | AH21: 1.373 | AI21: 1.393 | AJ21: 1.458 | AK21: 1.561
A22: =A21+1 -> 15 | B22: 44709.583 | C22: =D22*100 -> 173.1 | D22: 1.731 | F22: =D22-0.5 -> 1.231 | L22: 15 | M22: 43613 | N22: {=TRANSPOSE(D344:D367)} -> 1.696 | O22: 1.816 | P22: 1.903 | Q22: 1.968 | R22: 2.012 | S22: 2 | T22: 1.913 | U22: 1.82 | V22: 1.722 | W22: 1.648 | X22: 1.6 | Y22: 1.581 | Z22: 1.608 | AA22: 1.664 | AB22: 1.743 | AC22: 1.78 | AD22: 1.718 | AE22: 1.617 | AF22: 1.493 | AG22: 1.368 | AH22: 1.243 | AI22: 1.198 | AJ22: 1.238 | AK22: 1.388
A23: =A22+1 -> 16 | B23: 44709.625 | C23: =D23*100 -> 188.9 | D23: 1.889 | F23: =D23-0.5 -> 1.389 | L23: 16 | M23: 43614 | N23: {=TRANSPOSE(D368:D391)} -> 1.592 | O23: 1.819 | P23: 2.048 | Q23: 2.238 | R23: 2.348 | S23: 2.309 | T23: 2.2 | U23: 2.009 | V23: 1.797 | W23: 1.61 | X23: 1.48 | Y23: 1.4 | Z23: 1.454 | AA23: 1.516 | AB23: 1.607 | AC23: 1.69 | AD23: 1.69 | AE23: 1.619 | AF23: 1.472 | AG23: 1.301 | AH23: 1.126 | AI23: 1.025 | AJ23: 1.028 | AK23: 1.153
A24: =A23+1 -> 17 | B24: 44709.667 | C24: =D24*100 -> 194.9 | D24: 1.949 | F24: =D24-0.5 -> 1.449 | L24: 17 | M24: 43615 | N24: {=TRANSPOSE(D392:D415)} -> 1.409 | O24: 1.714 | P24: 2.026 | Q24: 2.315 | R24: 2.521 | S24: 2.597 | T24: 2.545 | U24: 2.338 | V24: 2.061 | W24: 1.756 | X24: 1.526 | Y24: 1.375 | Z24: 1.337 | AA24: 1.409 | AB24: 1.519 | AC24: 1.613 | AD24: 1.65 | AE24: 1.596 | AF24: 1.472 | AG24: 1.308 | AH24: 1.126 | AI24: 0.944 | AJ24: 0.884 | AK24: 0.936
A25: =A24+1 -> 18 | B25: 44709.708 | C25: =D25*100 -> 190 | D25: 1.9 | F25: =D25-0.5 -> 1.4 | L25: 18 | M25: 43616 | N25: {=TRANSPOSE(D416:D439)} -> 1.159 | O25: 1.49 | P25: 1.871 | Q25: 2.257 | R25: 2.554 | S25: 2.73 | T25: 2.747 | U25: 2.598 | V25: 2.319 | W25: 1.99 | X25: 1.692 | Y25: 1.422 | Z25: 1.297 | AA25: 1.29 | AB25: 1.386 | AC25: 1.497 | AD25: 1.578 | AE25: 1.575 | AF25: 1.469 | AG25: 1.319 | AH25: 1.134 | AI25: 0.947 | AJ25: 0.781 | AK25: 0.748
A26: =A25+1 -> 19 | B26: 44709.75 | C26: =D26*100 -> 173.3 | D26: 1.733 | F26: =D26-0.5 -> 1.233 | L26: 19 | M26: 43617 | N26: {=TRANSPOSE(D440:D463)} -> 0.889 | O26: 1.194 | P26: 1.614 | Q26: 2.089 | R26: 2.474 | S26: 2.769 | T26: 2.88 | U26: 2.812 | V26: 2.568 | W26: 2.225 | X26: 1.904 | Y26: 1.585 | Z26: 1.381 | AA26: 1.281 | AB26: 1.295 | AC26: 1.425 | AD26: 1.492 | AE26: 1.559 | AF26: 1.511 | AG26: 1.368 | AH26: 1.19 | AI26: 1.001 | AJ26: 0.83 | AK26: 0.653
A27: =A26+1 -> 20 | B27: 44709.792 | C27: =D27*100 -> 155 | D27: 1.55 | F27: =D27-0.5 -> 1.05 | L27: 20 | M27: 43618 | N27: {=TRANSPOSE(D464:D487)} -> 0.652 | O27: 0.868 | P27: 1.252 | Q27: 1.748 | R27: 2.259 | S27: 2.645 | T27: 2.87 | U27: 2.889 | V27: 2.711 | W27: 2.422 | X27: 2.108 | Y27: 1.785 | Z27: 1.55 | AA27: 1.382 | AB27: 1.325 | AC27: 1.385 | AD27: 1.498 | AE27: 1.577 | AF27: 1.584 | AG27: 1.475 | AH27: 1.295 | AI27: 1.054 | AJ27: 0.808 | AK27: 0.626
A28: =A27+1 -> 21 | B28: 44709.833 | C28: =D28*100 -> 132.4 | D28: 1.324 | F28: =D28-0.5 -> 0.824 | L28: 21 | M28: 43619 | N28: {=TRANSPOSE(D488:D511)} -> 0.56 | O28: 0.685 | P28: 0.958 | Q28: 1.426 | R28: 1.921 | S28: 2.375 | T28: 2.725 | U28: 2.862 | V28: 2.815 | W28: 2.61 | X28: 2.273 | Y28: 1.958 | Z28: 1.71 | AA28: 1.524 | AB28: 1.419 | AC28: 1.39 | AD28: 1.505 | AE28: 1.614 | AF28: 1.687 | AG28: 1.621 | AH28: 1.505 | AI28: 1.254 | AJ28: 1.012 | AK28: 0.815
A29: =A28+1 -> 22 | B29: 44709.875 | C29: =D29*100 -> 110.8 | D29: 1.108 | F29: =D29-0.5 -> 0.608 | L29: 22 | M29: 43620 | N29: {=TRANSPOSE(D512:D535)} -> 0.688 | O29: 0.615 | P29: 0.778 | Q29: 1.11 | R29: 1.597 | S29: 2.085 | T29: 2.466 | U29: 2.685 | V29: 2.704 | W29: 2.648 | X29: 2.427 | Y29: 2.081 | Z29: 1.789 | AA29: 1.628 | AB29: 1.467 | AC29: 1.445 | AD29: 1.515 | AE29: 1.622 | AF29: 1.712 | AG29: 1.734 | AH29: 1.658 | AI29: 1.5 | AJ29: 1.291 | AK29: 1.058
A30: =A29+1 -> 23 | B30: 44709.917 | C30: =D30*100 -> 96.9 | D30: 0.969 | F30: =D30-0.5 -> 0.469 | L30: 23 | M30: 43621 | N30: {=TRANSPOSE(D536:D559)} -> 0.834 | O30: 0.712 | P30: 0.728 | Q30: 0.91 | R30: 1.268 | S30: 1.765 | T30: 2.197 | U30: 2.532 | V30: 2.642 | W30: 2.58 | X30: 2.443 | Y30: 2.171 | Z30: 1.897 | AA30: 1.656 | AB30: 1.479 | AC30: 1.405 | AD30: 1.467 | AE30: 1.608 | AF30: 1.747 | AG30: 1.824 | AH30: 1.821 | AI30: 1.683 | AJ30: 1.485 | AK30: 1.287
A31: =A30+1 -> 24 | B31: 44709.958 | C31: =D31*100 -> 99.1 | D31: 0.991 | F31: =D31-0.5 -> 0.491 | L31: 24 | M31: 43622 | N31: {=TRANSPOSE(D560:D583)} -> 1.118 | O31: 0.939 | P31: 0.892 | Q31: 0.973 | R31: 1.186 | S31: 1.524 | T31: 1.959 | U31: 2.321 | V31: 2.504 | W31: 2.501 | X31: 2.411 | Y31: 2.238 | Z31: 1.998 | AA31: 1.766 | AB31: 1.55 | AC31: 1.407 | AD31: 1.414 | AE31: 1.545 | AF31: 1.7 | AG31: 1.817 | AH31: 1.881 | AI31: 1.844 | AJ31: 1.719 | AK31: 1.537
A32: =A31+1 -> 25 | B32: 44710 | C32: =D32*100 -> 113.8 | D32: 1.138 | F32: =D32-0.5 -> 0.638 | L32: 25 | M32: 43623 | N32: {=TRANSPOSE(D584:D607)} -> 1.349 | O32: 1.219 | P32: 1.116 | Q32: 1.139 | R32: 1.22 | S32: 1.435 | T32: 1.768 | U32: 2.088 | V32: 2.303 | W32: 2.379 | X32: 2.338 | Y32: 2.221 | Z32: 2.042 | AA32: 1.849 | AB32: 1.614 | AC32: 1.425 | AD32: 1.379 | AE32: 1.431 | AF32: 1.524 | AG32: 1.676 | AH32: 1.78 | AI32: 1.831 | AJ32: 1.81 | AK32: 1.679
A33: =A32+1 -> 26 | B33: 44710.042 | C33: =D33*100 -> 143.9 | D33: 1.439 | F33: =D33-0.5 -> 0.939 | L33: 26 | M33: 43624 | N33: {=TRANSPOSE(D608:D631)} -> 1.569 | O33: 1.433 | P33: 1.338 | Q33: 1.34 | R33: 1.381 | S33: 1.467 | T33: 1.657 | U33: 1.912 | V33: 2.087 | W33: 2.185 | X33: 2.219 | Y33: 2.17 | Z33: 2.057 | AA33: 1.855 | AB33: 1.653 | AC33: 1.464 | AD33: 1.334 | AE33: 1.279 | AF33: 1.337 | AG33: 1.429 | AH33: 1.54 | AI33: 1.644 | AJ33: 1.761 | AK33: 1.796
A34: =A33+1 -> 27 | B34: 44710.083 | C34: =D34*100 -> 184.7 | D34: 1.847 | F34: =D34-0.5 -> 1.347 | L34: 27 | M34: 43625 | N34: {=TRANSPOSE(D632:D655)} -> 1.79 | O34: 1.724 | P34: 1.617 | Q34: 1.566 | R34: 1.532 | S34: 1.568 | T34: 1.665 | U34: 1.784 | V34: 1.938 | W34: 1.973 | X34: 1.97 | Y34: 1.944 | Z34: 1.824 | AA34: 1.735 | AB34: 1.637 | AC34: 1.481 | AD34: 1.332 | AE34: 1.247 | AF34: 1.196 | AG34: 1.214 | AH34: 1.318 | AI34: 1.466 | AJ34: 1.6 | AK34: 1.699
A35: =A34+1 -> 28 | B35: 44710.125 | C35: =D35*100 -> 222.3 | D35: 2.223 | F35: =D35-0.5 -> 1.723 | L35: 28 | M35: 43626 | N35: {=TRANSPOSE(D656:D679)} -> 1.77 | O35: 1.805 | P35: 1.829 | Q35: 1.826 | R35: 1.788 | S35: 1.737 | T35: 1.697 | U35: 1.728 | V35: 1.756 | W35: 1.8 | X35: 1.831 | Y35: 1.809 | Z35: 1.76 | AA35: 1.709 | AB35: 1.617 | AC35: 1.524 | AD35: 1.419 | AE35: 1.314 | AF35: 1.221 | AG35: 1.171 | AH35: 1.149 | AI35: 1.244 | AJ35: 1.385 | AK35: 1.567
A36: =A35+1 -> 29 | B36: 44710.167 | C36: =D36*100 -> 249.1 | D36: 2.491 | F36: =D36-0.5 -> 1.991 | L36: 29 | M36: 43627 | N36: {=TRANSPOSE(D680:D703)} -> 1.719 | O36: 1.887 | P36: 2.007 | Q36: 2.053 | R36: 2.038 | S36: 1.972 | T36: 1.92 | U36: 1.847 | V36: 1.757 | W36: 1.684 | X36: 1.635 | Y36: 1.654 | Z36: 1.668 | AA36: 1.672 | AB36: 1.668 | AC36: 1.588 | AD36: 1.495 | AE36: 1.399 | AF36: 1.262 | AG36: 1.144 | AH36: 1.114 | AI36: 1.13 | AJ36: 1.204 | AK36: 1.35
A37: =A36+1 -> 30 | B37: 44710.208 | C37: =D37*100 -> 258.1 | D37: 2.581 | F37: =D37-0.5 -> 2.081 | L37: 30 | M37: 43628 | N37: {=TRANSPOSE(D704:D727)} -> 1.564 | O37: 1.812 | P37: 2.038 | Q37: 2.191 | R37: 2.251 | S37: 2.233 | T37: 2.145 | U37: 2.001 | V37: 1.812 | W37: 1.653 | X37: 1.553 | Y37: 1.503 | Z37: 1.511 | AA37: 1.57 | AB37: 1.5615 | AC37: 1.553 | AD37: 1.483 | AE37: 1.42 | AF37: 1.311 | AG37: 1.22 | AH37: 1.108 | AI37: 1.045 | AJ37: 1.009 | AK37: 1.109
A38: =A37+1 -> 31 | B38: 44710.25 | C38: =D38*100 -> 251.9 | D38: 2.519 | F38: =D38-0.5 -> 2.019
A39: =A38+1 -> 32 | B39: 44710.292 | C39: =D39*100 -> 232.6 | D39: 2.326 | F39: =D39-0.5 -> 1.826
A40: =A39+1 -> 33 | B40: 44710.333 | C40: =D40*100 -> 202.4 | D40: 2.024 | F40: =D40-0.5 -> 1.524
A41: =A40+1 -> 34 | B41: 44710.375 | C41: =D41*100 -> 171.9 | D41: 1.719 | F41: =D41-0.5 -> 1.219
A42: =A41+1 -> 35 | B42: 44710.417 | C42: =D42*100 -> 144.1 | D42: 1.441 | F42: =D42-0.5 -> 0.941
...

Sheet data asli
U5: Tabel 1
A6: PENGUKURAN PASANG SURUT (per 1 Jam) | U6: =A6 -> PENGUKURAN PASANG SURUT (per 1 Jam)
A7: PROYEK | B7: : Pantai Sanur, Bali | M7: Equipment : AWLR Tide Master | U7: =A7 -> PROYEK | V7: =B7 -> : Pantai Sanur, Bali
A8: LOKASI | B8: : Kabupaten Denpasar Selatan | U8: =A8 -> LOKASI | V8: =B8 -> : Kabupaten Denpasar Selatan
B10: TANGGAL / Januari -Februari | V10: =B10 -> TANGGAL / Januari -Februari
A11: JAM | B11: 28 | C11: 29 | D11: 30 | E11: 31 | F11: 1 | G11: 2 | H11: 3 | I11: 4 | J11: 5 | K11: 6 | L11: 7 | M11: 8 | N11: 9 | O11: 10 | P11: 11 | Q11: 32 | R11: 33 | S11: 34 | V11: =B11 -> 28 | W11: =C11 -> 29 | X11: =D11 -> 30 | Y11: =E11 -> 31 | Z11: =F11 -> 1 | AA11: =G11 -> 2 | AB11: =H11 -> 3 | AC11: =I11 -> 4 | ... AJ11: =P11 -> 11
A12: 00:00 | B12: ='data asli x100'!C8/100 -> 1.36 | C12: ='data asli x100'!C32/100 -> 1.138 | D12: ='data asli x100'!C56/100 -> 0.906 | E12: ='data asli x100'!C80/100 -> 0.743 | F12: ='data asli x100'!C104/100 -> 0.687 | G12: ='data asli x100'!C128/100 -> 0.658 | H12: ='data asli x100'!C152/100 -> 0.74 | I12: ='data asli x100'!C176/100 -> 0.797 | J12: ='data asli x100'!C200/100 -> 0.905 | K12: ='data asli x100'!C224/100 -> 1.047 | L12: ='data asli x100'!C248/100 -> 1.197 | M12: ='data asli x100'!C272/100 -> 1.373 | N12: ='data asli x100'!C296/100 -> 1.496 | O12: ='data asli x100'!C320/100 -> 1.62 | P12: ='data asli x100'!C344/100 -> 1.696 | Q12: =SUM(B12:P12) -> 16.363 | R12: =A12 -> 00:00 | S12: 1 | U12: =A12 -> 00:00
A13: 01:00 | B13: ='data asli x100'!C9/100 -> 1.655 | C13: ='data asli x100'!C33/100 -> 1.439 | D13: ='data asli x100'!C57/100 -> 1.231 | E13: ='data asli x100'!C81/100 -> 1.009 | F13: ='data asli x100'!C105/100 -> 0.864 | G13: ='data asli x100'!C129/100 -> 0.75 | H13: ='data asli x100'!C153/100 -> 0.754 | I13: ='data asli x100'!C177/100 -> 0.734 | J13: ='data asli x100'!C201/100 -> 0.786 | K13: ='data asli x100'!C225/100 -> 0.906 | L13: ='data asli x100'!C249/100 -> 1.058 | M13: ='data asli x100'!C273/100 -> 1.271 | N13: ='data asli x100'!C297/100 -> 1.437 | O13: ='data asli x100'!C321/100 -> 1.676 | P13: ='data asli x100'!C345/100 -> 1.816 | Q13: =SUM(B13:P13) -> 17.386 | R13: =A13 -> 01:00 | S13: 5 | U13: =A13 -> 01:00
A14: 02:00 | B14: ='data asli x100'!C10/100 -> 1.983 | C14: ='data asli x100'!C34/100 -> 1.847 | D14: ='data asli x100'!C58/100 -> 1.627 | E14: ='data asli x100'!C82/100 -> 1.395 | F14: ='data asli x100'!C106/100 -> 1.246 | G14: ='data asli x100'!C130/100 -> 1.061 | H14: ='data asli x100'!C154/100 -> 0.947 | I14: ='data asli x100'!C178/100 -> 0.857 | J14: ='data asli x100'!C202/100 -> 0.845 | K14: ='data asli x100'!C226/100 -> 0.871 | L14: ='data asli x100'!C250/100 -> 1.028 | M14: ='data asli x100'!C274/100 -> 1.234 | N14: ='data asli x100'!C298/100 -> 1.431 | O14: ='data asli x100'!C322/100 -> 1.669 | P14: ='data asli x100'!C346/100 -> 1.903 | Q14: =SUM(B14:P14) -> 19.944 | R14: =A14 -> 02:00 | S14: 9 | U14: =A14 -> 02:00
A15: 03:00 | B15: ='data asli x100'!C11/100 -> 2.247 | C15: ='data asli x100'!C35/100 -> 2.223 | D15: ='data asli x100'!C59/100 -> 2.055 | E15: ='data asli x100'!C83/100 -> 1.884 | F15: ='data asli x100'!C107/100 -> 1.701 | G15: ='data asli x100'!C131/100 -> 1.493 | H15: ='data asli x100'!C155/100 -> 1.305 | I15: ='data asli x100'!C179/100 -> 1.16 | J15: ='data asli x100'!C203/100 -> 1.07 | K15: ='data asli x100'!C227/100 -> 1.024 | L15: ='data asli x100'!C251/100 -> 1.1 | M15: ='data asli x100'!C275/100 -> 1.273 | N15: ='data asli x100'!C299/100 -> 1.466 | O15: ='data asli x100'!C323/100 -> 1.699 | P15: ='data asli x100'!C347/100 -> 1.968 | Q15: =SUM(B15:P15) -> 23.668 | R15: =A15 -> 03:00 | S15: 13 | U15: =A15 -> 03:00
A16: 04:00 | B16: ='data asli x100'!C12/100 -> 2.39 | C16: ='data asli x100'!C36/100 -> 2.491 | D16: ='data asli x100'!C60/100 -> 2.456 | E16: ='data asli x100'!C84/100 -> 2.352 | F16: ='data asli x100'!C108/100 -> 2.193 | G16: ='data asli x100'!C132/100 -> 1.999 | H16: ='data asli x100'!C156/100 -> 1.754 | I16: ='data asli x100'!C180/100 -> 1.54 | J16: ='data asli x100'!C204/100 -> 1.413 | K16: ='data asli x100'!C228/100 -> 1.314 | L16: ='data asli x100'!C252/100 -> 1.307 | M16: ='data asli x100'!C276/100 -> 1.352 | N16: ='data asli x100'!C300/100 -> 1.539 | O16: ='data asli x100'!C324/100 -> 1.714 | P16: ='data asli x100'!C348/100 -> 2.012 | Q16: =SUM(B16:P16) -> 27.826 | R16: =A16 -> 04:00 | S16: 17 | U16: =A16 -> 04:00
A17: 05:00 | B17: ='data asli x100'!C13/100 -> 2.43 | C17: ='data asli x100'!C37/100 -> 2.581 | D17: ='data asli x100'!C61/100 -> 2.714 | E17: ='data asli x100'!C85/100 -> 2.696 | F17: ='data asli x100'!C109/100 -> 2.595 | G17: ='data asli x100'!C133/100 -> 2.435 | H17: ='data asli x100'!C157/100 -> 2.185 | I17: ='data asli x100'!C181/100 -> 1.989 | J17: ='data asli x100'!C205/100 -> 1.792 | K17: ='data asli x100'!C229/100 -> 1.668 | L17: ='data asli x100'!C253/100 -> 1.593 | M17: ='data asli x100'!C277/100 -> 1.526 | N17: ='data asli x100'!C301/100 -> 1.636 | O17: ='data asli x100'!C325/100 -> 1.714 | P17: ='data asli x100'!C349/100 -> 2 | Q17: =SUM(B17:P17) -> 31.554 | R17: =A17 -> 05:00 | S17: 21 | U17: =A17 -> 05:00
A18: 06:00 | B18: ='data asli x100'!C14/100 -> 2.317 | C18: ='data asli x100'!C38/100 -> 2.519 | D18: ='data asli x100'!C62/100 -> 2.728 | E18: ='data asli x100'!C86/100 -> 2.815 | F18: ='data asli x100'!C110/100 -> 2.818 | G18: ='data asli x100'!C134/100 -> 2.745 | H18: ='data asli x100'!C158/100 -> 2.547 | I18: ='data asli x100'!C182/100 -> 2.356 | J18: ='data asli x100'!C206/100 -> 2.179 | K18: ='data asli x100'!C230/100 -> 1.993 | L18: ='data asli x100'!C254/100 -> 1.886 | M18: ='data asli x100'!C278/100 -> 1.739 | N18: ='data asli x100'!C302/100 -> 1.707 | O18: ='data asli x100'!C326/100 -> 1.712 | P18: ='data asli x100'!C350/100 -> 1.913 | Q18: =SUM(B18:P18) -> 33.974 | R18: =A18 -> 06:00 | S18: 25 | U18: =A18 -> 06:00
A19: 07:00 | B19: ='data asli x100'!C15/100 -> 2.121 | C19: ='data asli x100'!C39/100 -> 2.326 | D19: ='data asli x100'!C63/100 -> 2.552 | E19: ='data asli x100'!C87/100 -> 2.738 | F19: ='data asli x100'!C111/100 -> 2.84 | G19: ='data asli x100'!C135/100 -> 2.846 | H19: ='data asli x100'!C159/100 -> 2.758 | I19: ='data asli x100'!C183/100 -> 2.595 | J19: ='data asli x100'!C207/100 -> 2.442 | K19: ='data asli x100'!C231/100 -> 2.25 | L19: ='data asli x100'!C255/100 -> 2.096 | M19: ='data asli x100'!C279/100 -> 1.905 | N19: ='data asli x100'!C303/100 -> 1.797 | O19: ='data asli x100'!C327/100 -> 1.73 | P19: ='data asli x100'!C351/100 -> 1.82 | Q19: =SUM(B19:P19) -> 34.816 | R19: =A19 -> 07:00 | S19: 29 | U19: =A19 -> 07:00
A20: 08:00 | B20: ='data asli x100'!C16/100 -> 1.884 | C20: ='data asli x100'!C40/100 -> 2.024 | D20: ='data asli x100'!C64/100 -> 2.228 | E20: ='data asli x100'!C88/100 -> 2.46 | F20: ='data asli x100'!C112/100 -> 2.657 | G20: ='data asli x100'!C136/100 -> 2.758 | H20: ='data asli x100'!C160/100 -> 2.773 | I20: ='data asli x100'!C184/100 -> 2.689 | J20: ='data asli x100'!C208/100 -> 2.563 | K20: ='data asli x100'!C232/100 -> 2.402 | L20: ='data asli x100'!C256/100 -> 2.241 | M20: ='data asli x100'!C280/100 -> 2.039 | N20: ='data asli x100'!C304/100 -> 1.843 | O20: ='data asli x100'!C328/100 -> 1.752 | P20: ='data asli x100'!C352/100 -> 1.722 | Q20: =SUM(B20:P20) -> 34.035 | R20: =A20 -> 08:00 | S20: 33 | U20: =A20 -> 08:00
A21: 09:00 | B21: ='data asli x100'!C17/100 -> 1.637 | C21: ='data asli x100'!C41/100 -> 1.719 | D21: ='data asli x100'!C65/100 -> 1.828 | E21: ='data asli x100'!C89/100 -> 2.028 | F21: ='data asli x100'!C113/100 -> 2.288 | G21: ='data asli x100'!C137/100 -> 2.506 | H21: ='data asli x100'!C161/100 -> 2.598 | I21: ='data asli x100'!C185/100 -> 2.586 | J21: ='data asli x100'!C209/100 -> 2.552 | K21: ='data asli x100'!C233/100 -> 2.422 | L21: ='data asli x100'!C257/100 -> 2.303 | M21: ='data asli x100'!C281/100 -> 2.087 | N21: ='data asli x100'!C305/100 -> 1.874 | O21: ='data asli x100'!C329/100 -> 1.723 | P21: ='data asli x100'!C353/100 -> 1.648 | Q21: =SUM(B21:P21) -> 31.799 | R21: =A21 -> 09:00 | S21: 37 | U21: =A21 -> 09:00
A22: 10:00 | B22: ='data asli x100'!C18/100 -> 1.454 | C22: ='data asli x100'!C42/100 -> 1.441 | D22: ='data asli x100'!C66/100 -> 1.485 | E22: ='data asli x100'!C90/100 -> 1.653 | F22: ='data asli x100'!C114/100 -> 1.882 | G22: ='data asli x100'!C138/100 -> 2.123 | H22: ='data asli x100'!C162/100 -> 2.278 | I22: ='data asli x100'!C186/100 -> 2.339 | J22: ='data asli x100'!C210/100 -> 2.406 | K22: ='data asli x100'!C234/100 -> 2.357 | L22: ='data asli x100'!C258/100 -> 2.247 | M22: ='data asli x100'!C282/100 -> 2.077 | N22: ='data asli x100'!C306/100 -> 1.899 | O22: ='data asli x100'!C330/100 -> 1.715 | P22: ='data asli x100'!C354/100 -> 1.6 | Q22: =SUM(B22:P22) -> 28.956 | R22: =A22 -> 10:00 | S22: 41 | U22: =A22 -> 10:00
A23: 11:00 | B23: ='data asli x100'!C19/100 -> 1.354 | C23: ='data asli x100'!C43/100 -> 1.253 | D23: ='data asli x100'!C67/100 -> 1.22 | E23: ='data asli x100'!C91/100 -> 1.345 | F23: ='data asli x100'!C115/100 -> 1.515 | G23: ='data asli x100'!C139/100 -> 1.749 | H23: ='data asli x100'!C163/100 -> 1.887 | I23: ='data asli x100'!C187/100 -> 1.991 | J23: ='data asli x100'!C211/100 -> 2.115 | K23: ='data asli x100'!C235/100 -> 2.183 | L23: ='data asli x100'!C259/100 -> 2.124 | M23: ='data asli x100'!C283/100 -> 2.036 | N23: ='data asli x100'!C307/100 -> 1.924 | O23: ='data asli x100'!C331/100 -> 1.739 | P23: ='data asli x100'!C355/100 -> 1.581 | Q23: =SUM(B23:P23) -> 26.016 | R23: =A23 -> 11:00 | S23: 45 | U23: =A23 -> 11:00
... A35: 23:00 | B35: ='data asli x100'!C31/100 -> 0.991 | C35: ='data asli x100'!C55/100 -> 0.754 | D35: ='data asli x100'!C79/100 -> 0.702 | E35: ='data asli x100'!C103/100 -> 0.738 | F35: ='data asli x100'!C127/100 -> 0.762 | G35: ='data asli x100'!C151/100 -> 0.904 | H35: ='data asli x100'!C175/100 -> 1.023 | I35: ='data asli x100'!C199/100 -> 1.124 | J35: ='data asli x100'!C223/100 -> 1.254 | K35: ='data asli x100'!C247/100 -> 1.375 | L35: ='data asli x100'!C271/100 -> 1.495 | M35: ='data asli x100'!C295/100 -> 1.61 | N35: ='data asli x100'!C319/100 -> 1.569 | O35: ='data asli x100'!C343/100 -> 1.561 | P35: ='data asli x100'!C367/100 -> 1.388 | Q35: =SUM(B35:P35) -> 17.25 | R35: =A35 -> 23:00 | S35: 93 | U35: =A35 -> 23:00
A36: jumlah : | B36: =SUM(B12:B35) -> 40.957 | C36: =SUM(C12:C35) -> 39.722 | D36: =SUM(D12:D35) -> 39.619 | E36: =SUM(E12:E35) -> 39.402 | F36: =SUM(F12:F35) -> 39.861 | G36: =SUM(G12:G35) -> 40.467 | H36: =SUM(H12:H35) -> 40.263 | I36: =SUM(I12:I35) -> 39.8155 | ... P36: =SUM(P12:P35) -> 39.737
B37: =B36/96 -> 0.42663542 | C37: =C36/96 -> 0.41377083 | D37: =D36/96 -> 0.41269792 | E37: =E36/96 -> 0.4104375 | F37: =F36/96 -> 0.41521875 | G37: =G36/96 -> 0.42153125 | H37: =H36/96 -> 0.41940625 | I37: =I36/96 -> 0.41474479 | ... P37: =P36/96 -> 0.41392708 | Q37: =IF(S37=#REF!,"Good...","Not Good Man!!!!!") -> #REF! | S37: =SUM(B36:P36) -> 599.3395 | V37: =MAX($B$12:$P$35) -> 2.846 | W37: =V37-$V$38 -> 1.1811681 | X37: =W37-W39 -> 2.188
Q38: =S37/30 -> 19.977983 | V38: =AVERAGE($B$12:$P$35) -> 1.6648319 | W38: =V38-$V$38 -> 0
V39: =MIN($B$12:$P$35) -> 0.658 | W39: =V39-$V$38 -> -1.0068319

Sheet skemA1
A1: Skema 1 : Susunan hasil pengamatan data pasut
A3: No. | B3: Tgl | C3: Bacaan Skala pada jam satuan cm | AA3: Jumlah | AB3: Rata2
C4: 00 | D4: 01 | E4: 02 | F4: 03 | G4: 04 | H4: 05 | I4: 06 | J4: 07 | K4: 08 | L4: 09 | M4: 10 | N4: 11 | O4: 12 | P4: 13 | Q4: 14 | R4: 15 | S4: 16 | T4: 17 | U4: 18 | V4: 19 | W4: 20 | X4: 21 | Y4: 22 | Z4: 23
A5: 1 | B5: 44709 | C5: {=TRANSPOSE('data asli x100'!C8:C31)} -> 136 | D5: 165.5 | E5: 198.3 | F5: 224.7 | G5: 239 | H5: 243 | I5: 231.7 | J5: 212.1 | K5: 188.4 | L5: 163.7 | M5: 145.4 | N5: 135.4 | O5: 142 | P5: 156.1 | Q5: 173.1 | R5: 188.9 | S5: 194.9 | T5: 190 | U5: 173.3 | V5: 155 | W5: 132.4 | X5: 110.8 | Y5: 96.9 | Z5: 99.1 | AA5: =SUM(C5:Z5) -> 4095.7 | AB5: =AVERAGE(C5:Z5) -> 170.65417 | AD5: 8 | AE5: 31
A6: 2 | B6: =B5+1 -> 44710 | C6: {=TRANSPOSE('data asli x100'!C32:C55)} -> 113.8 | D6: 143.9 | E6: 184.7 | F6: 222.3 | G6: 249.1 | H6: 258.1 | I6: 251.9 | J6: 232.6 | K6: 202.4 | L6: 171.9 | M6: 144.1 | N6: 125.3 | O6: 123.2 | P6: 133.2 | Q6: 150 | R6: 169.3 | S6: 183.3 | T6: 184 | U6: 174.2 | V6: 158.3 | W6: 133.2 | X6: 106.7 | Y6: 81.3 | Z6: 75.4 | AA6: =SUM(C6:Z6) -> 3972.2 | AB6: =AVERAGE(C6:Z6) -> 165.50833 | AD6: =AE5+1 -> 32 | AE6: =AD6+(AE5-AD5) -> 55
A7: 3 | B7: =B6+1 -> 44711 | C7: {=TRANSPOSE('data asli x100'!C56:C79)} -> 90.6 | D7: 123.1 | E7: 162.7 | F7: 205.5 | G7: 245.6 | H7: 271.4 | I7: 272.8 | J7: 255.2 | K7: 222.8 | L7: 182.8 | M7: 148.5 | N7: 122 | O7: 113.6 | P7: 123.4 | Q7: 143.4 | R7: 164.1 | S7: 177.8 | T7: 182.1 | U7: 178.7 | V7: 162.6 | W7: 139.9 | X7: 114.6 | Y7: 88.5 | Z7: 70.2 | AA7: =SUM(C7:Z7) -> 3961.9 | AB7: =AVERAGE(C7:Z7) -> 165.07917 | AD7: =AE6+1 -> 56 | AE7: =AD7+(AE6-AD6) -> 79
A8: 4 | B8: =B7+1 -> 44712 | C8: {=TRANSPOSE('data asli x100'!C80:C103)} -> 74.3 | D8: 100.9 | E8: 139.5 | F8: 188.4 | G8: 235.2 | H8: 269.6 | I8: 281.5 | J8: 273.8 | K8: 246 | L8: 202.8 | M8: 165.3 | N8: 134.5 | O8: 118 | P8: 115.2 | Q8: 126.1 | R8: 147 | S8: 166.8 | T8: 177.1 | U8: 176.5 | V8: 165.3 | W8: 144.4 | X8: 122.6 | Y8: 95.6 | Z8: 73.8 | AA8: =SUM(C8:Z8) -> 3940.2 | AB8: =AVERAGE(C8:Z8) -> 164.175 | AD8: =AE7+1 -> 80 | AE8: =AD8+(AE7-AD7) -> 103
A9: 5 | B9: =B8+1 -> 44713 | C9: {=TRANSPOSE('data asli x100'!C104:C127)} -> 68.7 | D9: 86.4 | E9: 124.6 | F9: 170.1 | G9: 219.3 | H9: 259.5 | I9: 281.8 | J9: 284 | K9: 265.7 | L9: 228.8 | M9: 188.2 | N9: 151.5 | O9: 127 | P9: 116.9 | Q9: 122.5 | R9: 137.5 | S9: 159.4 | T9: 178.4 | U9: 183.9 | V9: 174.5 | W9: 155.4 | X9: 129.5 | Y9: 96.3 | Z9: 76.2 | AA9: =SUM(C9:Z9) -> 3986.1 | AB9: =AVERAGE(C9:Z9) -> 166.0875 | AD9: =AE8+1 -> 104 | AE9: =AD9+(AE8-AD8) -> 127
A10: 6 | B10: =B9+1 -> 44714 | C10: {=TRANSPOSE('data asli x100'!C128:C151)} -> 65.8 | D10: 75 | E10: 106.1 | F10: 149.3 | G10: 199.9 | H10: 243.5 | I10: 274.5 | J10: 284.6 | K10: 275.8 | L10: 250.6 | M10: 212.3 | N10: 174.9 | O10: 142.9 | P10: 126.1 | Q10: 123.1 | R10: 137.2 | S10: 158.8 | T10: 176.9 | U10: 181.3 | V10: 177.7 | W10: 164.1 | X10: 140.8 | Y10: 115.1 | Z10: 90.4 | AA10: =SUM(C10:Z10) -> 4046.7 | AB10: =AVERAGE(C10:Z10) -> 168.6125 | AD10: =AE9+1 -> 128 | AE10: =AD10+(AE9-AD9) -> 151
A11: 7 | B11: =B10+1 -> 44715 | C11: {=TRANSPOSE('data asli x100'!C152:C175)} -> 74 | D11: 75.4 | E11: 94.7 | F11: 130.5 | G11: 175.4 | H11: 218.5 | I11: 254.7 | J11: 275.8 | K11: 277.3 | L11: 259.8 | M11: 227.8 | N11: 188.7 | O11: 156.2 | P11: 134.9 | Q11: 128 | R11: 135 | S11: 152.7 | T11: 168 | U11: 177.9 | V11: 176.6 | W11: 168.3 | X11: 147.5 | Y11: 126.3 | Z11: 102.3 | AA11: =SUM(C11:Z11) -> 4026.3 | AB11: =AVERAGE(C11:Z11) -> 167.7625 | AD11: =AE10+1 -> 152 | AE11: =AD11+(AE10-AD10) -> 175
A12: 8 | B12: =B11+1 -> 44716 | C12: {=TRANSPOSE('data asli x100'!C176:C199)} -> 79.7 | D12: 73.4 | E12: 85.7 | F12: 116 | G12: 154 | H12: 198.9 | I12: 235.6 | J12: 259.5 | K12: 268.9 | L12: 258.6 | M12: 233.9 | N12: 199.1 | O12: 169.8 | P12: 143.55 | Q12: 131.9 | R12: 130.4 | S12: 142.1 | T12: 159.4 | U12: 174.8 | V12: 182 | W12: 177.1 | X12: 158.8 | Y12: 136 | Z12: 112.4 | AA12: =SUM(C12:Z12) -> 3981.55 | AB12: =AVERAGE(C12:Z12) -> 165.89792 | AD12: =AE11+1 -> 176 | AE12: =AD12+(AE11-AD11) -> 199
A13: 9 | B13: =B12+1 -> 44717 | C13: {=TRANSPOSE('data asli x100'!C200:C223)} -> 90.5 | D13: 78.6 | E13: 84.5 | F13: 107 | G13: 141.3 | H13: 179.2 | I13: 217.9 | J13: 244.2 | K13: 256.3 | L13: 255.2 | M13: 240.6 | N13: 211.5 | O13: 180.5 | P13: 156.4 | Q13: 143.9 | R13: 140.8 | S13: 147.9 | T13: 159.3 | U13: 172.1 | V13: 180.8 | W13: 180.5 | X13: 166.7 | Y13: 146 | Z13: 125.4 | AA13: =SUM(C13:Z13) -> 4007.1 | AB13: =AVERAGE(C13:Z13) -> 166.9625 | AD13: =AE12+1 -> 200 | AE13: =AD13+(AE12-AD12) -> 223
A14: 10 | B14: =B13+1 -> 44718 | C14: {=TRANSPOSE('data asli x100'!C224:C247)} -> 104.7 | D14: 90.6 | E14: 87.1 | F14: 102.4 | G14: 131.4 | H14: 166.8 | I14: 199.3 | J14: 225 | K14: 240.2 | L14: 242.2 | M14: 235.7 | N14: 218.3 | O14: 192.3 | P14: 170.5 | Q14: 155.6 | R14: 147.3 | S14: 147.9 | T14: 157.3 | U14: 167.3 | V14: 178.9 | W14: 183.2 | X14: 175.5 | Y14: 155.6 | Z14: 137.5 | AA14: =SUM(C14:Z14) -> 4012.6 | AB14: =AVERAGE(C14:Z14) -> 167.19167 | AD14: =AE13+1 -> 224 | AE14: =AD14+(AE13-AD13) -> 247
A15: 11 | B15: =B14+1 -> 44719 | C15: {=TRANSPOSE('data asli x100'!C248:C271)} -> 119.7 | D15: 105.8 | E15: 102.8 | F15: 110 | G15: 130.7 | H15: 159.3 | I15: 188.6 | J15: 209.6 | K15: 224.1 | L15: 230.3 | M15: 224.7 | N15: 212.4 | O15: 198.6 | P15: 180.8 | Q15: 162.9 | R15: 153.5 | S15: 150.2 | T15: 151.1 | U15: 159.5 | V15: 172.4 | W15: 179.6 | X15: 176.6 | Y15: 164 | Z15: 149.5 | AA15: =SUM(C15:Z15) -> 4016.7 | AB15: =AVERAGE(C15:Z15) -> 167.3625 | AD15: =AE14+1 -> 248 | AE15: =AD15+(AE14-AD14) -> 271
A16: 12 | B16: =B15+1 -> 44720 | C16: {=TRANSPOSE('data asli x100'!C272:C295)} -> 137.3 | D16: 127.1 | E16: 123.4 | F16: 127.3 | G16: 135.2 | H16: 152.6 | I16: 173.9 | J16: 190.5 | K16: 203.9 | L16: 208.7 | M16: 207.7 | N16: 203.6 | O16: 197.6 | P16: 187.3 | Q16: 176.5 | R16: 163.2 | S16: 157.8 | T16: 153.8 | U16: 154.4 | V16: 162.1 | W16: 170.4 | X16: 172.1 | Y16: 169.3 | Z16: 161 | AA16: =SUM(C16:Z16) -> 4016.7 | AB16: =AVERAGE(C16:Z16) -> 167.3625 | AD16: =AE15+1 -> 272 | AE16: =AD16+(AE15-AD15) -> 295
A17: 13 | B17: =B16+1 -> 44721 | C17: {=TRANSPOSE('data asli x100'!C296:C319)} -> 149.6 | D17: 143.7 | E17: 143.1 | F17: 146.6 | G17: 153.9 | H17: 163.6 | I17: 170.7 | J17: 179.7 | K17: 184.3 | L17: 187.4 | M17: 189.9 | N17: 192.4 | O17: 189.4 | P17: 183.5 | Q17: 178.9 | R17: 167.4 | S17: 157.6 | T17: 150.9 | U17: 146.8 | V17: 148.4 | W17: 152.7 | X17: 154.4 | Y17: 158.4 | Z17: 156.9 | AA17: =SUM(C17:Z17) -> 3950.2 | AB17: =AVERAGE(C17:Z17) -> 164.59167 | AD17: =AE16+1 -> 296 | AE17: =AD17+(AE16-AD16) -> 319
A18: 14 | B18: =B17+1 -> 44722 | C18: {=TRANSPOSE('data asli x100'!C320:C343)} -> 162 | D18: 167.6 | E18: 166.9 | F18: 169.9 | G18: 171.4 | H18: 171.4 | I18: 171.2 | J18: 173 | K18: 175.2 | L18: 172.3 | M18: 171.5 | N18: 173.9 | O18: 178.5 | P18: 182.2 | Q18: 182.3 | R18: 176.6 | S18: 168.4 | T18: 154.8 | U18: 142.2 | V18: 136.5 | W18: 137.3 | X18: 139.3 | Y18: 145.8 | Z18: 156.1 | AA18: =SUM(C18:Z18) -> 3946.3 | AB18: =AVERAGE(C18:Z18) -> 164.42917 | AD18: =AE17+1 -> 320 | AE18: =AD18+(AE17-AD17) -> 343
A19: 15 | B19: =B18+1 -> 44723 | C19: {=TRANSPOSE('data asli x100'!C344:C367)} -> 169.6 | D19: 181.6 | E19: 190.3 | F19: 196.8 | G19: 201.2 | H19: 200 | I19: 191.3 | J19: 182 | K19: 172.2 | L19: 164.8 | M19: 160 | N19: 158.1 | O19: 160.8 | P19: 166.4 | Q19: 174.3 | R19: 178 | S19: 171.8 | T19: 161.7 | U19: 149.3 | V19: 136.8 | W19: 124.3 | X19: 119.8 | Y19: 123.8 | Z19: 138.8 | AA19: =SUM(C19:Z19) -> 3973.7 | AB19: =AVERAGE(C19:Z19) -> 165.57083 | AD19: =AE18+1 -> 344 | AE19: =AD19+(AE18-AD18) -> 367
A20: 16 | B20: =B19+1 -> 44724 | C20: {=TRANSPOSE('data asli x100'!C368:C391)} -> 159.2 | D20: 181.9 | E20: 204.8 | F20: 223.8 | G20: 234.8 | H20: 230.9 | I20: 220 | J20: 200.9 | K20: 179.7 | L20: 161 | M20: 148 | N20: 140 | O20: 145.4 | P20: 151.6 | Q20: 160.7 | R20: 169 | S20: 169 | T20: 161.9 | U20: 147.2 | V20: 130.1 | W20: 112.6 | X20: 102.5 | Y20: 102.8 | Z20: 115.3 | AA20: =SUM(C20:Z20) -> 3953.1 | AB20: =AVERAGE(C20:Z20) -> 164.7125
A21: 17 | B21: =B20+1 -> 44725 | C21: {=TRANSPOSE('data asli x100'!C392:C415)} -> 140.9 | D21: 171.4 | E21: 202.6 | F21: 231.5 | G21: 252.1 | H21: 259.7 | I21: 254.5 | J21: 233.8 | K21: 206.1 | L21: 175.6 | M21: 152.6 | N21: 137.5 | O21: 133.7 | P21: 140.9 | Q21: 151.9 | R21: 161.3 | S21: 165 | T21: 159.6 | U21: 147.2 | V21: 130.8 | W21: 112.6 | X21: 94.4 | Y21: 88.4 | Z21: 93.6 | AA21: =SUM(C21:Z21) -> 3997.7 | AB21: =AVERAGE(C21:Z21) -> 166.57083
A22: 18 | B22: =B21+1 -> 44726 | C22: {=TRANSPOSE('data asli x100'!C416:C439)} -> 115.9 | D22: 149 | E22: 187.1 | F22: 225.7 | G22: 255.4 | H22: 273 | I22: 274.7 | J22: 259.8 | K22: 231.9 | L22: 199 | M22: 169.2 | N22: 142.2 | O22: 129.7 | P22: 129 | Q22: 138.6 | R22: 149.7 | S22: 157.8 | T22: 157.5 | U22: 146.9 | V22: 131.9 | W22: 113.4 | X22: 94.7 | Y22: 78.1 | Z22: 74.8 | AA22: =SUM(C22:Z22) -> 3985 | AB22: =AVERAGE(C22:Z22) -> 166.04167
A23: 19 | B23: =B22+1 -> 44727 | C23: {=TRANSPOSE('data asli x100'!C440:C463)} -> 88.9 | D23: 119.4 | E23: 161.4 | F23: 208.9 | G23: 247.4 | H23: 276.9 | I23: 288 | J23: 281.2 | K23: 256.8 | L23: 222.5 | M23: 190.4 | N23: 158.5 | O23: 138.1 | P23: 128.1 | Q23: 129.5 | R23: 142.5 | S23: 149.2 | T23: 155.9 | U23: 151.1 | V23: 136.8 | W23: 119 | X23: 100.1 | Y23: 83 | Z23: 65.3 | AA23: =SUM(C23:Z23) -> 3998.9 | AB23: =AVERAGE(C23:Z23) -> 166.62083
A24: 20 | B24: =B23+1 -> 44728 | C24: {=TRANSPOSE('data asli x100'!C464:C487)} -> 65.2 | D24: 86.8 | E24: 125.2 | F24: 174.8 | G24: 225.9 | H24: 264.5 | I24: 287 | J24: 288.9 | K24: 271.1 | L24: 242.2 | M24: 210.8 | N24: 178.5 | O24: 155 | P24: 138.2 | Q24: 132.5 | R24: 138.5 | S24: 149.8 | T24: 157.7 | U24: 158.4 | V24: 147.5 | W24: 129.5 | X24: 105.4 | Y24: 80.8 | Z24: 62.6 | AA24: =SUM(C24:Z24) -> 3976.8 | AB24: =AVERAGE(C24:Z24) -> 165.7
A25: 21 | B25: =B24+1 -> 44729 | C25: {=TRANSPOSE('data asli x100'!C488:C511)} -> 56 | D25: 68.5 | E25: 95.8 | F25: 142.6 | G25: 192.1 | H25: 237.5 | I25: 272.5 | J25: 286.2 | K25: 281.5 | L25: 261 | M25: 227.3 | N25: 195.8 | O25: 171 | P25: 152.4 | Q25: 141.9 | R25: 139 | S25: 150.5 | T25: 161.4 | U25: 168.7 | V25: 162.1 | W25: 150.5 | X25: 125.4 | Y25: 101.2 | Z25: 81.5 | AA25: =SUM(C25:Z25) -> 4022.4 | AB25: =AVERAGE(C25:Z25) -> 167.6
A26: 22 | B26: =B25+1 -> 44730 | C26: {=TRANSPOSE('data asli x100'!C512:C535)} -> 68.8 | D26: 61.5 | E26: 77.8 | F26: 111 | G26: 159.7 | H26: 208.5 | I26: 246.6 | J26: 268.5 | K26: 270.4 | L26: 264.8 | M26: 242.7 | N26: 208.1 | O26: 178.9 | P26: 162.8 | Q26: 146.7 | R26: 144.5 | S26: 151.5 | T26: 162.2 | U26: 171.2 | V26: 173.4 | W26: 165.8 | X26: 150 | Y26: 129.1 | Z26: 105.8 | AA26: =SUM(C26:Z26) -> 4030.3 | AB26: =AVERAGE(C26:Z26) -> 167.92917
A27: 23 | B27: =B26+1 -> 44731 | C27: {=TRANSPOSE('data asli x100'!C536:C559)} -> 83.4 | D27: 71.2 | E27: 72.8 | F27: 91 | G27: 126.8 | H27: 176.5 | I27: 219.7 | J27: 253.2 | K27: 264.2 | L27: 258 | M27: 244.3 | N27: 217.1 | O27: 189.7 | P27: 165.6 | Q27: 147.9 | R27: 140.5 | S27: 146.7 | T27: 160.8 | U27: 174.7 | V27: 182.4 | W27: 182.1 | X27: 168.3 | Y27: 148.5 | Z27: 128.7 | AA27: =SUM(C27:Z27) -> 4014.1 | AB27: =AVERAGE(C27:Z27) -> 167.25417
A28: 24 | B28: =B27+1 -> 44732 | C28: {=TRANSPOSE('data asli x100'!C560:C583)} -> 111.8 | D28: 93.9 | E28: 89.2 | F28: 97.3 | G28: 118.6 | H28: 152.4 | I28: 195.9 | J28: 232.1 | K28: 250.4 | L28: 250.1 | M28: 241.1 | N28: 223.8 | O28: 199.8 | P28: 176.6 | Q28: 155 | R28: 140.7 | S28: 141.4 | T28: 154.5 | U28: 170 | V28: 181.7 | W28: 188.1 | X28: 184.4 | Y28: 171.9 | Z28: 153.7 | AA28: =SUM(C28:Z28) -> 4074.4 | AB28: =AVERAGE(C28:Z28) -> 169.76667
A29: 25 | B29: =B28+1 -> 44733 | C29: {=TRANSPOSE('data asli x100'!C584:C607)} -> 134.9 | D29: 121.9 | E29: 111.6 | F29: 113.9 | G29: 122 | H29: 143.5 | I29: 176.8 | J29: 208.8 | K29: 230.3 | L29: 237.9 | M29: 233.8 | N29: 222.1 | O29: 204.2 | P29: 184.9 | Q29: 161.4 | R29: 142.5 | S29: 137.9 | T29: 143.1 | U29: 152.4 | V29: 167.6 | W29: 178 | X29: 183.1 | Y29: 181 | Z29: 167.9 | AA29: =SUM(C29:Z29) -> 4061.5 | AB29: =AVERAGE(C29:Z29) -> 169.22917
A30: 26 | B30: =B29+1 -> 44734 | C30: {=TRANSPOSE('data asli x100'!C608:C631)} -> 156.9 | D30: 143.3 | E30: 133.8 | F30: 134 | G30: 138.1 | H30: 146.7 | I30: 165.7 | J30: 191.2 | K30: 208.7 | L30: 218.5 | M30: 221.9 | N30: 217 | O30: 205.7 | P30: 185.5 | Q30: 165.3 | R30: 146.4 | S30: 133.4 | T30: 127.9 | U30: 133.7 | V30: 142.9 | W30: 154 | X30: 164.4 | Y30: 176.1 | Z30: 179.6 | AA30: =SUM(C30:Z30) -> 3990.7 | AB30: =AVERAGE(C30:Z30) -> 166.27917
A31: 27 | B31: =B30+1 -> 44735 | C31: {=TRANSPOSE('data asli x100'!C632:C655)} -> 179 | D31: 172.4 | E31: 161.7 | F31: 156.6 | G31: 153.2 | H31: 156.8 | I31: 166.5 | J31: 178.4 | K31: 193.8 | L31: 197.3 | M31: 197 | N31: 194.4 | O31: 182.4 | P31: 173.5 | Q31: 163.7 | R31: 148.1 | S31: 133.2 | T31: 124.7 | U31: 119.6 | V31: 121.4 | W31: 131.8 | X31: 146.6 | Y31: 160 | Z31: 169.9 | AA31: =SUM(C31:Z31) -> 3882 | AB31: =AVERAGE(C31:Z31) -> 161.75 | AQ31: =3.492-0.919 -> 2.573
A32: 28 | B32: =B31+1 -> 44736 | C32: {=TRANSPOSE('data asli x100'!C656:C679)} -> 177 | D32: 180.5 | E32: 182.9 | F32: 182.6 | G32: 178.8 | H32: 173.7 | I32: 169.7 | J32: 172.8 | K32: 175.6 | L32: 180 | M32: 183.1 | N32: 180.9 | O32: 176 | P32: 170.9 | Q32: 161.7 | R32: 152.4 | S32: 141.9 | T32: 131.4 | U32: 122.1 | V32: 117.1 | W32: 114.9 | X32: 124.4 | Y32: 138.5 | Z32: 156.7 | AA32: =SUM(C32:Z32) -> 3845.6 | AB32: =AVERAGE(C32:Z32) -> 160.23333
A33: 29 | B33: =B32+1 -> 44737 | C33: {=TRANSPOSE('data asli x100'!C680:C703)} -> 171.9 | D33: 188.7 | E33: 200.7 | F33: 205.3 | G33: 203.8 | H33: 197.2 | I33: 192 | J33: 184.7 | K33: 175.7 | L33: 168.4 | M33: 163.5 | N33: 165.4 | O33: 166.8 | P33: 167.2 | Q33: 166.8 | R33: 158.8 | S33: 149.5 | T33: 139.9 | U33: 126.2 | V33: 114.4 | W33: 111.4 | X33: 113 | Y33: 120.4 | Z33: 135 | AA33: =SUM(C33:Z33) -> 3886.7 | AB33: =AVERAGE(C33:Z33) -> 161.94583
A35: Keterangan : | C35: Air Tertinggi | G35: : | H35: =MAX(C5:Z33) -> 288.9 | I35: cm
C36: Air Terendah | G36: : | H36: =MIN(C5:Z33) -> 56 | I36: cm
C37: Duduk Tengah | G37: : | H37: ='Duduk Tengah'!L44 -> 166.53241 | I37: cm
G38: =H35-H36 -> 232.9 | J38: =H35-H36 -> 232.9
A41: Waktu tengah = | C41: 11
C44: 0.554 | D44: 0.891 | E44: 1.021 | F44: 1.27 | G44: 1.447 | H44: 1.462 | I44: 1.491 | J44: 1.316 | K44: 1.087 | L44: 1.054 | M44: 0.75 | N44: 0.663 | O44: 0.758 | P44: 1.053 | Q44: 1.157 | R44: 1.371 | S44: 1.612 | T44: 1.621 | U44: 1.354 | V44: 1.28 | W44: 1.886 | X44: 0.832 | Y44: 0.601 | Z44: 0.462 | AA44: 0.414

Sheet Tabel 2
B2: Tabel 2. Konstanta pengali dalam menyusun Skema 2.
C4: Jam Pengamatan | AD4: =skemA1!B5 -> 44709
C5: 00 | D5: 01 | E5: 02 | F5: 03 | G5: 04 | H5: 05 | I5: 06 | J5: 07 | K5: 08 | L5: 09 | M5: 10 | N5: 11 | O5: 12 | P5: 13 | Q5: 14 | R5: 15 | S5: 16 | T5: 17 | U5: 18 | V5: 19 | W5: 20 | X5: 21 | Y5: 22 | Z5: 23 | AD5: Jam | AE5: Tide Elev. | AF5: X1 | AJ5: Y1 | AN5: X2 | AR5: Y2 | AV5: X4 | AZ5: Y4
B6: X1 | C6: -1 | D6: -1 | E6: -1 | F6: -1 | G6: -1 | H6: -1 | I6: 1 | J6: 1 | K6: 1 | L6: 1 | M6: 1 | N6: 1 | O6: 1 | P6: 1 | Q6: 1 | R6: 1 | S6: 1 | T6: 1 | U6: -1 | V6: -1 | W6: -1 | X6: -1 | Y6: -1 | Z6: -1 | AF6: Multiplier Factor | AG6: Result | AJ6: Multiplier Factor | AK6: Result | AN6: Multiplier Factor | AO6: Result | AR6: Multiplier Factor | AS6: Result | AV6: Multiplier Factor | AW6: Result | AZ6: Multiplier Factor | BA6: Result
B7: Y1 | C7: -1 | D7: -1 | E7: -1 | F7: -1 | G7: -1 | H7: -1 | I7: -1 | J7: -1 | K7: -1 | L7: -1 | M7: -1 | N7: -1 | O7: 1 | P7: 1 | Q7: 1 | R7: 1 | S7: 1 | T7: 1 | U7: 1 | V7: 1 | W7: 1 | X7: 1 | Y7: 1 | Z7: 1 | AG7: + | AH7: 0 | AI7: - | AK7: + | AL7: 0 | AM7: - | AO7: + | AP7: 0 | AQ7: - | AS7: + | AT7: 0 | AU7: - | AW7: + | AX7: 0 | AY7: - | BA7: + | BB7: 0 | BC7: -
B8: X2 | C8: 1 | D8: 1 | E8: 1 | F8: -1 | G8: -1 | H8: -1 | I8: -1 | J8: -1 | K8: -1 | L8: 1 | M8: 1 | N8: 1 | O8: 1 | P8: 1 | Q8: 1 | R8: -1 | S8: -1 | T8: -1 | U8: -1 | V8: -1 | W8: -1 | X8: 1 | Y8: 1 | Z8: 1 | AD8: {=TRANSPOSE(C5:Z5)} -> 00 | AE8: {=TRANSPOSE(skemA1!C5:Z5)} -> 136 | AF8: {=TRANSPOSE(C6:Z6)} -> -1 | AG8: =IF(AF8>0,AF8*$AE8,"") | AH8: =IF(AF8=0,AF8*$AE8,"") | AI8: =IF(AF8<0,AF8*$AE8,"") -> -136 | AJ8: {=TRANSPOSE(C7:Z7)} -> -1 | AK8: =IF(AJ8>0,AJ8*$AE8,"") | AL8: =IF(AJ8=0,AJ8*$AE8,"") | AM8: =IF(AJ8<0,AJ8*$AE8,"") -> -136 | AN8: {=TRANSPOSE(C8:Z8)} -> 1 | AO8: =IF(AN8>0,AN8*$AE8,"") -> 136 | AP8: =IF(AN8=0,AN8*$AE8,"") | AQ8: =IF(AN8<0,AN8*$AE8,"") | AR8: {=TRANSPOSE(C9:Z9)} -> 1 | AS8: =IF(AR8>0,AR8*$AE8,"") -> 136 | AT8: =IF(AR8=0,AR8*$AE8,"") | AU8: =IF(AR8<0,AR8*$AE8,"") | AV8: {=TRANSPOSE(C10:Z10)} -> 1 | AW8: =IF(AV8>0,AV8*$AE8,"") -> 136 | AX8: =IF(AV8=0,AV8*$AE8,"") | AY8: =IF(AV8<0,AV8*$AE8,"") | AZ8: {=TRANSPOSE(C11:Z11)} -> 1 | BA8: =IF(AZ8>0,AZ8*$AE8,"") -> 136 | BB8: =IF(AZ8=0,AZ8*$AE8,"") | BC8: =IF(AZ8<0,AZ8*$AE8,"")
B9: Y2 | C9: 1 | D9: 1 | E9: 1 | F9: 1 | G9: 1 | H9: 1 | I9: -1 | J9: -1 | K9: -1 | L9: -1 | M9: -1 | N9: -1 | O9: 1 | P9: 1 | Q9: 1 | R9: 1 | S9: 1 | T9: 1 | U9: -1 | V9: -1 | W9: -1 | X9: -1 | Y9: -1 | Z9: -1 | AD9: 01 | AE9: 165.5 | AF9: -1 | AG9: =IF(AF9>0,AF9*$AE9,"") | AH9: =IF(AF9=0,AF9*$AE9,"") | AI9: =IF(AF9<0,AF9*$AE9,"") -> -165.5 | AJ9: -1 | AK9: =IF(AJ9>0,AJ9*$AE9,"") | AL9: =IF(AJ9=0,AJ9*$AE9,"") | AM9: =IF(AJ9<0,AJ9*$AE9,"") -> -165.5 | AN9: 1 | AO9: =IF(AN9>0,AN9*$AE9,"") -> 165.5 | AP9: =IF(AN9=0,AN9*$AE9,"") | AQ9: =IF(AN9<0,AN9*$AE9,"") | AR9: 1 | AS9: =IF(AR9>0,AR9*$AE9,"") -> 165.5 | AT9: =IF(AR9=0,AR9*$AE9,"") | AU9: =IF(AR9<0,AR9*$AE9,"") | AV9: 0 | AW9: =IF(AV9>0,AV9*$AE9,"") | AX9: =IF(AV9=0,AV9*$AE9,"") -> 0 | AY9: =IF(AV9<0,AV9*$AE9,"") | AZ9: 1 | BA9: =IF(AZ9>0,AZ9*$AE9,"") -> 165.5 | BB9: =IF(AZ9=0,AZ9*$AE9,"") | BC9: =IF(AZ9<0,AZ9*$AE9,"")
B10: X4 | C10: 1 | D10: 0 | E10: -1 | F10: -1 | G10: 0 | H10: 1 | I10: 1 | J10: 0 | K10: -1 | L10: -1 | M10: 0 | N10: 1 | O10: 1 | P10: 0 | Q10: -1 | R10: -1 | S10: 0 | T10: 1 | U10: 1 | V10: 0 | W10: -1 | X10: -1 | Y10: 0 | Z10: 1 | AD10: 02 | AE10: 198.3 | AF10: -1 | AG10: =IF(AF10>0,AF10*$AE10,"") | AH10: =IF(AF10=0,AF10*$AE10,"") | AI10: =IF(AF10<0,AF10*$AE10,"") -> -198.3 | AJ10: -1 | AK10: =IF(AJ10>0,AJ10*$AE10,"") | AL10: =IF(AJ10=0,AJ10*$AE10,"") | AM10: =IF(AJ10<0,AJ10*$AE10,"") -> -198.3 | AN10: 1 | AO10: =IF(AN10>0,AN10*$AE10,"") -> 198.3 | AP10: =IF(AN10=0,AN10*$AE10,"") | AQ10: =IF(AN10<0,AN10*$AE10,"") | AR10: 1 | AS10: =IF(AR10>0,AR10*$AE10,"") -> 198.3 | AT10: =IF(AR10=0,AR10*$AE10,"") | AU10: =IF(AR10<0,AR10*$AE10,"") | AV10: -1 | AW10: =IF(AV10>0,AV10*$AE10,"") | AX10: =IF(AV10=0,AV10*$AE10,"") | AY10: =IF(AV10<0,AV10*$AE10,"") -> -198.3 | AZ10: 1 | BA10: =IF(AZ10>0,AZ10*$AE10,"") -> 198.3 | BB10: =IF(AZ10=0,AZ10*$AE10,"") | BC10: =IF(AZ10<0,AZ10*$AE10,"")
B11: Y4 | C11: 1 | D11: 1 | E11: 1 | F11: -1 | G11: -1 | H11: -1 | I11: 1 | J11: 1 | K11: 1 | L11: -1 | M11: -1 | N11: -1 | O11: 1 | P11: 1 | Q11: 1 | R11: -1 | S11: -1 | T11: -1 | U11: 1 | V11: 1 | W11: 1 | X11: -1 | Y11: -1 | Z11: -1 | AD11: 03 | AE11: 224.7 | AF11: -1 | AG11: =IF(AF11>0,AF11*$AE11,"") | AH11: =IF(AF11=0,AF11*$AE11,"") | AI11: =IF(AF11<0,AF11*$AE11,"") -> -224.7 | AJ11: -1 | AK11: =IF(AJ11>0,AJ11*$AE11,"") | AL11: =IF(AJ11=0,AJ11*$AE11,"") | AM11: =IF(AJ11<0,AJ11*$AE11,"") -> -224.7 | AN11: -1 | AO11: =IF(AN11>0,AN11*$AE11,"") | AP11: =IF(AN11=0,AN11*$AE11,"") | AQ11: =IF(AN11<0,AN11*$AE11,"") -> -224.7 | AR11: 1 | AS11: =IF(AR11>0,AR11*$AE11,"") -> 224.7 | AT11: =IF(AR11=0,AR11*$AE11,"") | AU11: =IF(AR11<0,AR11*$AE11,"") | AV11: -1 | AW11: =IF(AV11>0,AV11*$AE11,"") | AX11: =IF(AV11=0,AV11*$AE11,"") | AY11: =IF(AV11<0,AV11*$AE11,"") -> -224.7 | AZ11: -1 | BA11: =IF(AZ11>0,AZ11*$AE11,"") | BB11: =IF(AZ11=0,AZ11*$AE11,"") | BC11: =IF(AZ11<0,AZ11*$AE11,"") -> -224.7
AD12: 04 | AE12: 239 | AF12: -1 | AG12: =IF(AF12>0,AF12*$AE12,"") | AH12: =IF(AF12=0,AF12*$AE12,"") | AI12: =IF(AF12<0,AF12*$AE12,"") -> -239 | AJ12: -1 | AK12: =IF(AJ12>0,AJ12*$AE12,"") | AL12: =IF(AJ12=0,AJ12*$AE12,"") | AM12: =IF(AJ12<0,AJ12*$AE12,"") -> -239 | AN12: -1 | AO12: =IF(AN12>0,AN12*$AE12,"") | AP12: =IF(AN12=0,AN12*$AE12,"") | AQ12: =IF(AN12<0,AN12*$AE12,"") -> -239 | AR12: 1 | AS12: =IF(AR12>0,AR12*$AE12,"") -> 239 | AT12: =IF(AR12=0,AR12*$AE12,"") | AU12: =IF(AR12<0,AR12*$AE12,"") | AV12: 0 | AW12: =IF(AV12>0,AV12*$AE12,"") | AX12: =IF(AV12=0,AV12*$AE12,"") -> 0 | AY12: =IF(AV12<0,AV12*$AE12,"") | AZ12: -1 | BA12: =IF(AZ12>0,AZ12*$AE12,"") | BB12: =IF(AZ12=0,AZ12*$AE12,"") | BC12: =IF(AZ12<0,AZ12*$AE12,"") -> -239
AD13: 05 | AE13: 243 | AF13: -1 | AG13: =IF(AF13>0,AF13*$AE13,"") | AH13: =IF(AF13=0,AF13*$AE13,"") | AI13: =IF(AF13<0,AF13*$AE13,"") -> -243 | AJ13: -1 | AK13: =IF(AJ13>0,AJ13*$AE13,"") | AL13: =IF(AJ13=0,AJ13*$AE13,"") | AM13: =IF(AJ13<0,AJ13*$AE13,"") -> -243 | AN13: -1 | AO13: =IF(AN13>0,AN13*$AE13,"") | AP13: =IF(AN13=0,AN13*$AE13,"") | AQ13: =IF(AN13<0,AN13*$AE13,"") -> -243 | AR13: 1 | AS13: =IF(AR13>0,AR13*$AE13,"") -> 243 | AT13: =IF(AR13=0,AR13*$AE13,"") | AU13: =IF(AR13<0,AR13*$AE13,"") | AV13: 1 | AW13: =IF(AV13>0,AV13*$AE13,"") -> 243 | AX13: =IF(AV13=0,AV13*$AE13,"") | AY13: =IF(AV13<0,AV13*$AE13,"") | AZ13: -1 | BA13: =IF(AZ13>0,AZ13*$AE13,"") | BB13: =IF(AZ13=0,AZ13*$AE13,"") | BC13: =IF(AZ13<0,AZ13*$AE13,"") -> -243
AD14: 06 | AE14: 231.7 | AF14: 1 | AG14: =IF(AF14>0,AF14*$AE14,"") -> 231.7 | AH14: =IF(AF14=0,AF14*$AE14,"") | AI14: =IF(AF14<0,AF14*$AE14,"") | AJ14: -1 | AK14: =IF(AJ14>0,AJ14*$AE14,"") | AL14: =IF(AJ14=0,AJ14*$AE14,"") | AM14: =IF(AJ14<0,AJ14*$AE14,"") -> -231.7 | AN14: -1 | AO14: =IF(AN14>0,AN14*$AE14,"") | AP14: =IF(AN14=0,AN14*$AE14,"") | AQ14: =IF(AN14<0,AN14*$AE14,"") -> -231.7 | AR14: -1 | AS14: =IF(AR14>0,AR14*$AE14,"") | AT14: =IF(AR14=0,AR14*$AE14,"") | AU14: =IF(AR14<0,AR14*$AE14,"") -> -231.7 | AV14: 1 | AW14: =IF(AV14>0,AV14*$AE14,"") -> 231.7 | AX14: =IF(AV14=0,AV14*$AE14,"") | AY14: =IF(AV14<0,AV14*$AE14,"") | AZ14: 1 | BA14: =IF(AZ14>0,AZ14*$AE14,"") -> 231.7 | BB14: =IF(AZ14=0,AZ14*$AE14,"") | BC14: =IF(AZ14<0,AZ14*$AE14,"")
AD15: 07 | AE15: 212.1 | AF15: 1 | AG15: =IF(AF15>0,AF15*$AE15,"") -> 212.1 | AH15: =IF(AF15=0,AF15*$AE15,"") | AI15: =IF(AF15<0,AF15*$AE15,"") | AJ15: -1 | AK15: =IF(AJ15>0,AJ15*$AE15,"") | AL15: =IF(AJ15=0,AJ15*$AE15,"") | AM15: =IF(AJ15<0,AJ15*$AE15,"") -> -212.1 | AN15: -1 | AO15: =IF(AN15>0,AN15*$AE15,"") | AP15: =IF(AN15=0,AN15*$AE15,"") | AQ15: =IF(AN15<0,AN15*$AE15,"") -> -212.1 | AR15: -1 | AS15: =IF(AR15>0,AR15*$AE15,"") | AT15: =IF(AR15=0,AR15*$AE15,"") | AU15: =IF(AR15<0,AR15*$AE15,"") -> -212.1 | AV15: 0 | AW15: =IF(AV15>0,AV15*$AE15,"") | AX15: =IF(AV15=0,AV15*$AE15,"") -> 0 | AY15: =IF(AV15<0,AV15*$AE15,"") | AZ15: 1 | BA15: =IF(AZ15>0,AZ15*$AE15,"") -> 212.1 | BB15: =IF(AZ15=0,AZ15*$AE15,"") | BC15: =IF(AZ15<0,AZ15*$AE15,"")
AD16: 08 | AE16: 188.4 | AF16: 1 | AG16: =IF(AF16>0,AF16*$AE16,"") -> 188.4 | AH16: =IF(AF16=0,AF16*$AE16,"") | AI16: =IF(AF16<0,AF16*$AE16,"") | AJ16: -1 | AK16: =IF(AJ16>0,AJ16*$AE16,"") | AL16: =IF(AJ16=0,AJ16*$AE16,"") | AM16: =IF(AJ16<0,AJ16*$AE16,"") -> -188.4 | AN16: -1 | AO16: =IF(AN16>0,AN16*$AE16,"") | AP16: =IF(AN16=0,AN16*$AE16,"") | AQ16: =IF(AN16<0,AN16*$AE16,"") -> -188.4 | AR16: -1 | AS16: =IF(AR16>0,AR16*$AE16,"") | AT16: =IF(AR16=0,AR16*$AE16,"") | AU16: =IF(AR16<0,AR16*$AE16,"") -> -188.4 | AV16: -1 | AW16: =IF(AV16>0,AV16*$AE16,"") | AX16: =IF(AV16=0,AV16*$AE16,"") | AY16: =IF(AV16<0,AV16*$AE16,"") -> -188.4 | AZ16: 1 | BA16: =IF(AZ16>0,AZ16*$AE16,"") -> 188.4 | BB16: =IF(AZ16=0,AZ16*$AE16,"") | BC16: =IF(AZ16<0,AZ16*$AE16,"")
AD17: 09 | AE17: 163.7 | AF17: 1 | AG17: =IF(AF17>0,AF17*$AE17,"") -> 163.7 | AH17: =IF(AF17=0,AF17*$AE17,"") | AI17: =IF(AF17<0,AF17*$AE17,"") | AJ17: -1 | AK17: =IF(AJ17>0,AJ17*$AE17,"") | AL17: =IF(AJ17=0,AJ17*$AE17,"") | AM17: =IF(AJ17<0,AJ17*$AE17,"") -> -163.7 | AN17: 1 | AO17: =IF(AN17>0,AN17*$AE17,"") -> 163.7 | AP17: =IF(AN17=0,AN17*$AE17,"") | AQ17: =IF(AN17<0,AN17*$AE17,"") | AR17: -1 | AS17: =IF(AR17>0,AR17*$AE17,"") | AT17: =IF(AR17=0,AR17*$AE17,"") | AU17: =IF(AR17<0,AR17*$AE17,"") -> -163.7 | AV17: -1 | AW17: =IF(AV17>0,AV17*$AE17,"") | AX17: =IF(AV17=0,AV17*$AE17,"") | AY17: =IF(AV17<0,AV17*$AE17,"") -> -163.7 | AZ17: -1 | BA17: =IF(AZ17>0,AZ17*$AE17,"") | BB17: =IF(AZ17=0,AZ17*$AE17,"") | BC17: =IF(AZ17<0,AZ17*$AE17,"") -> -163.7
AD18: 10 | AE18: 145.4 | AF18: 1 | AG18: =IF(AF18>0,AF18*$AE18,"") -> 145.4 | AH18: =IF(AF18=0,AF18*$AE18,"") | AI18: =IF(AF18<0,AF18*$AE18,"") | AJ18: -1 | AK18: =IF(AJ18>0,AJ18*$AE18,"") | AL18: =IF(AJ18=0,AJ18*$AE18,"") | AM18: =IF(AJ18<0,AJ18*$AE18,"") -> -145.4 | AN18: 1 | AO18: =IF(AN18>0,AN18*$AE18,"") -> 145.4 | AP18: =IF(AN18=0,AN18*$AE18,"") | AQ18: =IF(AN18<0,AN18*$AE18,"") | AR18: -1 | AS18: =IF(AR18>0,AR18*$AE18,"") | AT18: =IF(AR18=0,AR18*$AE18,"") | AU18: =IF(AR18<0,AR18*$AE18,"") -> -145.4 | AV18: 0 | AW18: =IF(AV18>0,AV18*$AE18,"") | AX18: =IF(AV18=0,AV18*$AE18,"") -> 0 | AY18: =IF(AV18<0,AV18*$AE18,"") | AZ18: -1 | BA18: =IF(AZ18>0,AZ18*$AE18,"") | BB18: =IF(AZ18=0,AZ18*$AE18,"") | BC18: =IF(AZ18<0,AZ18*$AE18,"") -> -145.4
AD19: 11 | AE19: 135.4 | AF19: 1 | AG19: =IF(AF19>0,AF19*$AE19,"") -> 135.4 | AH19: =IF(AF19=0,AF19*$AE19,"") | AI19: =IF(AF19<0,AF19*$AE19,"") | AJ19: -1 | AK19: =IF(AJ19>0,AJ19*$AE19,"") | AL19: =IF(AJ19=0,AJ19*$AE19,"") | AM19: =IF(AJ19<0,AJ19*$AE19,"") -> -135.4 | AN19: 1 | AO19: =IF(AN19>0,AN19*$AE19,"") -> 135.4 | AP19: =IF(AN19=0,AN19*$AE19,"") | AQ19: =IF(AN19<0,AN19*$AE19,"") | AR19: -1 | AS19: =IF(AR19>0,AR19*$AE19,"") | AT19: =IF(AR19=0,AR19*$AE19,"") | AU19: =IF(AR19<0,AR19*$AE19,"") -> -135.4 | AV19: 1 | AW19: =IF(AV19>0,AV19*$AE19,"") -> 135.4 | AX19: =IF(AV19=0,AV19*$AE19,"") | AY19: =IF(AV19<0,AV19*$AE19,"") | AZ19: -1 | BA19: =IF(AZ19>0,AZ19*$AE19,"") | BB19: =IF(AZ19=0,AZ19*$AE19,"") | BC19: =IF(AZ19<0,AZ19*$AE19,"") -> -135.4
AD20: 12 | AE20: 142 | AF20: 1 | AG20: =IF(AF20>0,AF20*$AE20,"") -> 142 | AH20: =IF(AF20=0,AF20*$AE20,"") | AI20: =IF(AF20<0,AF20*$AE20,"") | AJ20: 1 | AK20: =IF(AJ20>0,AJ20*$AE20,"") -> 142 | AL20: =IF(AJ20=0,AJ20*$AE20,"") | AM20: =IF(AJ20<0,AJ20*$AE20,"") | AN20: 1 | AO20: =IF(AN20>0,AN20*$AE20,"") -> 142 | AP20: =IF(AN20=0,AN20*$AE20,"") | AQ20: =IF(AN20<0,AN20*$AE20,"") | AR20: 1 | AS20: =IF(AR20>0,AR20*$AE20,"") -> 142 | AT20: =IF(AR20=0,AR20*$AE20,"") | AU20: =IF(AR20<0,AR20*$AE20,"") | AV20: 1 | AW20: =IF(AV20>0,AV20*$AE20,"") -> 142 | AX20: =IF(AV20=0,AV20*$AE20,"") | AY20: =IF(AV20<0,AV20*$AE20,"") | AZ20: 1 | BA20: =IF(AZ20>0,AZ20*$AE20,"") -> 142 | BB20: =IF(AZ20=0,AZ20*$AE20,"") | BC20: =IF(AZ20<0,AZ20*$AE20,"")
AD21: 13 | AE21: 156.1 | AF21: 1 | AG21: =IF(AF21>0,AF21*$AE21,"") -> 156.1 | AH21: =IF(AF21=0,AF21*$AE21,"") | AI21: =IF(AF21<0,AF21*$AE21,"") | AJ21: 1 | AK21: =IF(AJ21>0,AJ21*$AE21,"") -> 156.1 | AL21: =IF(AJ21=0,AJ21*$AE21,"") | AM21: =IF(AJ21<0,AJ21*$AE21,"") | AN21: 1 | AO21: =IF(AN21>0,AN21*$AE21,"") -> 156.1 | AP21: =IF(AN21=0,AN21*$AE21,"") | AQ21: =IF(AN21<0,AN21*$AE21,"") | AR21: 1 | AS21: =IF(AR21>0,AR21*$AE21,"") -> 156.1 | AT21: =IF(AR21=0,AR21*$AE21,"") | AU21: =IF(AR21<0,AR21*$AE21,"") | AV21: 0 | AW21: =IF(AV21>0,AV21*$AE21,"") | AX21: =IF(AV21=0,AV21*$AE21,"") -> 0 | AY21: =IF(AV21<0,AV21*$AE21,"") | AZ21: 1 | BA21: =IF(AZ21>0,AZ21*$AE21,"") -> 156.1 | BB21: =IF(AZ21=0,AZ21*$AE21,"") | BC21: =IF(AZ21<0,AZ21*$AE21,"")
AD22: 14 | AE22: 173.1 | AF22: 1 | AG22: =IF(AF22>0,AF22*$AE22,"") -> 173.1 | AH22: =IF(AF22=0,AF22*$AE22,"") | AI22: =IF(AF22<0,AF22*$AE22,"") | AJ22: 1 | AK22: =IF(AJ22>0,AJ22*$AE22,"") -> 173.1 | AL22: =IF(AJ22=0,AJ22*$AE22,"") | AM22: =IF(AJ22<0,AJ22*$AE22,"") | AN22: 1 | AO22: =IF(AN22>0,AN22*$AE22,"") -> 173.1 | AP22: =IF(AN22=0,AN22*$AE22,"") | AQ22: =IF(AN22<0,AN22*$AE22,"") | AR22: 1 | AS22: =IF(AR22>0,AR22*$AE22,"") -> 173.1 | AT22: =IF(AR22=0,AR22*$AE22,"") | AU22: =IF(AR22<0,AR22*$AE22,"") | AV22: -1 | AW22: =IF(AV22>0,AV22*$AE22,"") | AX22: =IF(AV22=0,AV22*$AE22,"") | AY22: =IF(AV22<0,AV22*$AE22,"") -> -173.1 | AZ22: 1 | BA22: =IF(AZ22>0,AZ22*$AE22,"") -> 173.1 | BB22: =IF(AZ22=0,AZ22*$AE22,"") | BC22: =IF(AZ22<0,AZ22*$AE22,"")
AD23: 15 | AE23: 188.9 | AF23: 1 | AG23: =IF(AF23>0,AF23*$AE23,"") -> 188.9 | AH23: =IF(AF23=0,AF23*$AE23,"") | AI23: =IF(AF23<0,AF23*$AE23,"") | AJ23: 1 | AK23: =IF(AJ23>0,AJ23*$AE23,"") -> 188.9 | AL23: =IF(AJ23=0,AJ23*$AE23,"") | AM23: =IF(AJ23<0,AJ23*$AE23,"") | AN23: -1 | AO23: =IF(AN23>0,AN23*$AE23,"") | AP23: =IF(AN23=0,AN23*$AE23,"") | AQ23: =IF(AN23<0,AN23*$AE23,"") -> -188.9 | AR23: 1 | AS23: =IF(AR23>0,AR23*$AE23,"") -> 188.9 | AT23: =IF(AR23=0,AR23*$AE23,"") | AU23: =IF(AR23<0,AR23*$AE23,"") | AV23: -1 | AW23: =IF(AV23>0,AV23*$AE23,"") | AX23: =IF(AV23=0,AV23*$AE23,"") | AY23: =IF(AV23<0,AV23*$AE23,"") -> -188.9 | AZ23: -1 | BA23: =IF(AZ23>0,AZ23*$AE23,"") | BB23: =IF(AZ23=0,AZ23*$AE23,"") | BC23: =IF(AZ23<0,AZ23*$AE23,"") -> -188.9
... AD31: 23 | AE31: 99.1 | AF31: -1 | AG31: =IF(AF31>0,AF31*$AE31,"") | AH31: =IF(AF31=0,AF31*$AE31,"") | AI31: =IF(AF31<0,AF31*$AE31,"") -> -99.1 | AJ31: 1 | AK31: =IF(AJ31>0,AJ31*$AE31,"") -> 99.1 | AL31: =IF(AJ31=0,AJ31*$AE31,"") | AM31: =IF(AJ31<0,AJ31*$AE31,"") | AN31: 1 | AO31: =IF(AN31>0,AN31*$AE31,"") -> 99.1 | AP31: =IF(AN31=0,AN31*$AE31,"") | AQ31: =IF(AN31<0,AN31*$AE31,"") | AR31: -1 | AS31: =IF(AR31>0,AR31*$AE31,"") | AT31: =IF(AR31=0,AR31*$AE31,"") | AU31: =IF(AR31<0,AR31*$AE31,"") -> -99.1 | AV31: 1 | AW31: =IF(AV31>0,AV31*$AE31,"") -> 99.1 | AX31: =IF(AV31=0,AV31*$AE31,"") | AY31: =IF(AV31<0,AV31*$AE31,"") | AZ31: -1 | BA31: =IF(AZ31>0,AZ31*$AE31,"") | BB31: =IF(AZ31=0,AZ31*$AE31,"") | BC31: =IF(AZ31<0,AZ31*$AE31,"") -> -99.1
AC32: =AD4 -> 44709 | AD32: Jumlah | AE32: =SUM(AE8:AE31) -> 4095.7 | AG32: =ABS(SUM(AG8:AG31)) -> 2121.7 | AI32: =ABS(SUM(AI8:AI31)) -> 1974 | AK32: =ABS(SUM(AK8:AK31)) -> 1812.5 | AM32: =ABS(SUM(AM8:AM31)) -> 2283.2 | AO32: =ABS(SUM(AO8:AO31)) -> 1722.3 | AQ32: =ABS(SUM(AQ8:AQ31)) -> 2373.4 | AS32: =ABS(SUM(AS8:AS31)) -> 2251.5 | AU32: =ABS(SUM(AU8:AU31)) -> 1844.2 | AW32: =ABS(SUM(AW8:AW31)) -> 1350.5 | AY32: =ABS(SUM(AY8:AY31)) -> 1380.3 | BA32: =ABS(SUM(BA8:BA31)) -> 2063.9 | BC32: =ABS(SUM(BC8:BC31)) -> 2031.8
AD34: =skemA1!B6 -> 44710
AD35: Jam | AE35: Tide Elev. | AF35: X1 | AJ35: Y1 | AN35: X2 | AR35: Y2 | AV35: X4 | AZ35: Y4
AF36: Multiplier Factor | AG36: Result | AJ36: Multiplier Factor | AK36: Result | AN36: Multiplier Factor | AO36: Result | AR36: Multiplier Factor | AS36: Result | AV36: Multiplier Factor | AW36: Result | AZ36: Multiplier Factor | BA36: Result
AG37: + | AH37: 0 | AI37: - | AK37: + | AL37: 0 | AM37: - | AO37: + | AP37: 0 | AQ37: - | AS37: + | AT37: 0 | AU37: - | AW37: + | AX37: 0 | AY37: - | BA37: + | BB37: 0 | BC37: -
AD38: {=TRANSPOSE($C$5:$Z$5)} -> 00 | AE38: {=TRANSPOSE(skemA1!$C$6:$Z$6)} -> 113.8 | AF38: {=TRANSPOSE($C$6:$Z$6)} -> -1 | AG38: =IF(AF38>0,AF38*$AE38,"") | AH38: =IF(AF38=0,AF38*$AE38,"") | AI38: =IF(AF38<0,AF38*$AE38,"") -> -113.8 | AJ38: {=TRANSPOSE($C$7:$Z$7)} -> -1 | AK38: =IF(AJ38>0,AJ38*$AE38,"") | AL38: =IF(AJ38=0,AJ38*$AE38,"") | AM38: =IF(AJ38<0,AJ38*$AE38,"") -> -113.8 | AN38: {=TRANSPOSE($C$8:$Z$8)} -> 1 | AO38: =IF(AN38>0,AN38*$AE38,"") -> 113.8 | AP38: =IF(AN38=0,AN38*$AE38,"") | AQ38: =IF(AN38<0,AN38*$AE38,"") | AR38: {=TRANSPOSE($C$9:$Z$9)} -> 1 | AS38: =IF(AR38>0,AR38*$AE38,"") -> 113.8 | AT38: =IF(AR38=0,AR38*$AE38,"") | AU38: =IF(AR38<0,AR38*$AE38,"") | AV38: {=TRANSPOSE($C$10:$Z$10)} -> 1 | AW38: =IF(AV38>0,AV38*$AE38,"") -> 113.8 | AX38: =IF(AV38=0,AV38*$AE38,"") | AY38: =IF(AV38<0,AV38*$AE38,"") | AZ38: {=TRANSPOSE($C$11:$Z$11)} -> 1 | BA38: =IF(AZ38>0,AZ38*$AE38,"") -> 113.8 | BB38: =IF(AZ38=0,AZ38*$AE38,"") | BC38: =IF(AZ38<0,AZ38*$AE38,"")
AD39: 01 | AE39: 143.9 | AF39: -1 | AG39: =IF(AF39>0,AF39*$AE39,"") | AH39: =IF(AF39=0,AF39*$AE39,"") | AI39: =IF(AF39<0,AF39*$AE39,"") -> -143.9 | AJ39: -1 | AK39: =IF(AJ39>0,AJ39*$AE39,"") | AL39: =IF(AJ39=0,AJ39*$AE39,"") | AM39: =IF(AJ39<0,AJ39*$AE39,"") -> -143.9 | AN39: 1 | AO39: =IF(AN39>0,AN39*$AE39,"") -> 143.9 | AP39: =IF(AN39=0,AN39*$AE39,"") | AQ39: =IF(AN39<0,AN39*$AE39,"") | AR39: 1 | AS39: =IF(AR39>0,AR39*$AE39,"") -> 143.9 | AT39: =IF(AR39=0,AR39*$AE39,"") | AU39: =IF(AR39<0,AR39*$AE39,"") | AV39: 0 | AW39: =IF(AV39>0,AV39*$AE39,"") | AX39: =IF(AV39=0,AV39*$AE39,"") -> 0 | AY39: =IF(AV39<0,AV39*$AE39,"") | AZ39: 1 | BA39: =IF(AZ39>0,AZ39*$AE39,"") -> 143.9 | BB39: =IF(AZ39=0,AZ39*$AE39,"") | BC39: =IF(AZ39<0,AZ39*$AE39,"")
AD40: 02 | AE40: 184.7 | AF40: -1 | AG40: =IF(AF40>0,AF40*$AE40,"") | AH40: =IF(AF40=0,AF40*$AE40,"") | AI40: =IF(AF40<0,AF40*$AE40,"") -> -184.7 | AJ40: -1 | AK40: =IF(AJ40>0,AJ40*$AE40,"") | AL40: =IF(AJ40=0,AJ40*$AE40,"") | AM40: =IF(AJ40<0,AJ40*$AE40,"") -> -184.7 | AN40: 1 | AO40: =IF(AN40>0,AN40*$AE40,"") -> 184.7 | AP40: =IF(AN40=0,AN40*$AE40,"") | AQ40: =IF(AN40<0,AN40*$AE40,"") | AR40: 1 | AS40: =IF(AR40>0,AR40*$AE40,"") -> 184.7 | AT40: =IF(AR40=0,AR40*$AE40,"") | AU40: =IF(AR40<0,AR40*$AE40,"") | AV40: -1 | AW40: =IF(AV40>0,AV40*$AE40,"") | AX40: =IF(AV40=0,AV40*$AE40,"") | AY40: =IF(AV40<0,AV40*$AE40,"") -> -184.7 | AZ40: 1 | BA40: =IF(AZ40>0,AZ40*$AE40,"") -> 184.7 | BB40: =IF(AZ40=0,AZ40*$AE40,"") | BC40: =IF(AZ40<0,AZ40*$AE40,"")
